Workbook

Sheet 계약리스트
A1: 계약번호 | B1: 계약일자 | C1: 차종 | D1: 차대번호 | E1: 차량번호 | F1: 색상 | G1: 정비여부 | H1: 보험연령 | I1: 일사용료 | J1: 사용일수 | K1: 보증금 | L1: 사업장 업체명 | M1: 사업자번호 | N1: 대표자명 | O1: 업체주소 | P1: 사업장 연락처 | Q1: 사업장 이메일 | R1: 대표자 주민번호 | S1: 대표자 연락처 | T1: 대표자 주소 | U1: 계약유형 | V1: 상품유형 | W1: 납입방법 | X1: 납입계좌 | Y1: 요금결제일 | Z1: 계약유형 | AA1: 상품유형 | AB1: 납입방법 | AC1: 납입계좌 | AD1: 요금결제일
A2: 1 | B2: 2026-04-24 | C2: UHR150 | D2: LWMTDKH95THJ00467 | E2: 1나88370 | F2: 화이트 | G2: 비포함 | H2: 만30세 | I2: 26400 | J2: 365 | K2: 300000 | L2: 중앙 오토바이 가수점 | M2: 737-55-00719 | N2: 안종식 | O2: 경기도 오산시 가장로 763, 1층 5,6호(가수동) | P2: 010-5813-7336 | Q2: jungang@example.com | R2: 820530-1046518 | S2: 010-5813-7336 | T2: 경기도 오산시 궐동로 77, 1층(궐동) | U2: 렌트 | V2: 인수형 | W2: 계좌이체 | X2: 기업은행 929-028075-04-011 포어스바이크(유) | Y2: 월2회(15일,말일) | Z2: 할부 판매 | AA2: 인수형 | AB2: 계좌이체 | AC2: 기업은행 929-028519-04-010 | AD2: 월2회(15일, 말일)

Sheet 계약서
L1: 계약번호입력→
B2: 이륜차 할부판매 계약서 | L2: 1
B3: 한국모터사이클리스 유한회사 | F3: 계약번호 | I3: =IFERROR(TEXT($L$2,"0000"),"") -> 0001
B5: ■ 차량 정보
B6: 차종 | C6: =IFERROR(IF(VLOOKUP($L$2,[1]계약리스트!$A$2:$AD$10000,3,0)="","",VLOOKUP($L$2,[1]계약리스트!$A$2:$AD$10000,3,0)),"") -> UHR150 | E6: 차량번호 | F6: =IFERROR(IF(VLOOKUP($L$2,[1]계약리스트!$A$2:$AD$10000,5,0)="","",VLOOKUP($L$2,[1]계약리스트!$A$2:$AD$10000,5,0)),"") -> 1나88370 | H6: 색상 | I6: =IFERROR(IF(VLOOKUP($L$2,[1]계약리스트!$A$2:$AD$10000,6,0)="","",VLOOKUP($L$2,[1]계약리스트!$A$2:$AD$10000,6,0)),"") -> 화이트
B7: 차대번호 | C7: =IFERROR(IF(VLOOKUP($L$2,[1]계약리스트!$A$2:$AD$10000,4,0)="","",VLOOKUP($L$2,[1]계약리스트!$A$2:$AD$10000,4,0)),"") -> LWMTDKH95THJ00467 | E7: 정비여부 | F7: =IFERROR(IF(VLOOKUP($L$2,[1]계약리스트!$A$2:$AD$10000,7,0)="","",VLOOKUP($L$2,[1]계약리스트!$A$2:$AD$10000,7,0)),"") -> 비포함 | H7: 계약일자 | I7: =IFERROR(IF(VLOOKUP($L$2,[1]계약리스트!$A$2:$AD$10000,2,0)="","",VLOOKUP($L$2,[1]계약리스트!$A$2:$AD$10000,2,0)),"") -> 2026-04-24
B9: ■ 계약자
B10: 업체명 | C10: =IFERROR(IF(VLOOKUP($L$2,[1]계약리스트!$A$2:$AD$10000,12,0)="","",VLOOKUP($L$2,[1]계약리스트!$A$2:$AD$10000,12,0)),"") -> 중앙 오토바이 가수점 | E10: 사업자번호 | F10: =IFERROR(IF(VLOOKUP($L$2,[1]계약리스트!$A$2:$AD$10000,13,0)="","",VLOOKUP($L$2,[1]계약리스트!$A$2:$AD$10000,13,0)),"") -> 737-55-00719 | H10: 대표자명 | I10: =IFERROR(IF(VLOOKUP($L$2,[1]계약리스트!$A$2:$AD$10000,14,0)="","",VLOOKUP($L$2,[1]계약리스트!$A$2:$AD$10000,14,0)),"") -> 안종식
B11: 연락처 | C11: =IFERROR(IF(VLOOKUP($L$2,[1]계약리스트!$A$2:$AD$10000,16,0)="","",VLOOKUP($L$2,[1]계약리스트!$A$2:$AD$10000,16,0)),"") -> 010-5813-7336 | E11: 업체주소 | F11: =IFERROR(IF(VLOOKUP($L$2,[1]계약리스트!$A$2:$AD$10000,15,0)="","",VLOOKUP($L$2,[1]계약리스트!$A$2:$AD$10000,15,0)),"") -> 경기도 오산시 가장로 763, 1층 5,6호(가수동)
B12: ※ 제출 서류 : 사업자등록증 사본, 대표자 신분증 사본
B14: ■ 연대보증인
B15: 성명 | C15: =IFERROR(IF(VLOOKUP($L$2,[1]계약리스트!$A$2:$AD$10000,14,0)="","",VLOOKUP($L$2,[1]계약리스트!$A$2:$AD$10000,14,0)),"") -> 안종식 | E15: 주민등록번호 | F15: =IFERROR(IF(VLOOKUP($L$2,[1]계약리스트!$A$2:$AD$10000,18,0)="","",VLOOKUP($L$2,[1]계약리스트!$A$2:$AD$10000,18,0)),"") -> 820530-1046518 | H15: 연락처 | I15: =IFERROR(IF(VLOOKUP($L$2,[1]계약리스트!$A$2:$AD$10000,19,0)="","",VLOOKUP($L$2,[1]계약리스트!$A$2:$AD$10000,19,0)),"") -> 010-5813-7336
B16: 주소 | C16: =IFERROR(IF(VLOOKUP($L$2,[1]계약리스트!$A$2:$AD$10000,20,0)="","",VLOOKUP($L$2,[1]계약리스트!$A$2:$AD$10000,20,0)),"") -> 경기도 오산시 궐동로 77, 1층(궐동)
B17: ※ 제출 서류 : 대표자 신분증 사본 | 보증 기한 : 2년 | 보증 한도 : 전체 이용료의 130%
B19: ■ 계약 조건
B20: 계약유형 | C20: =IFERROR(IF(VLOOKUP($L$2,계약리스트!$A$2:$AD$10000,21,0)="","",VLOOKUP($L$2,계약리스트!$A$2:$AD$10000,21,0)),"") -> 렌트 | E20: 상품유형 | F20: =IFERROR(IF(VLOOKUP($L$2,계약리스트!$A$2:$AD$10000,27,0)="","",VLOOKUP($L$2,계약리스트!$A$2:$AD$10000,27,0)),"") -> 인수형 | H20: 렌트기간 | I20: =IFERROR(VLOOKUP($L$2,계약리스트!$A$2:$AD$10000,10,0)&"일","") -> 365일
B21: 일사용료 (VAT포함) | C21: =IFERROR(TEXT(VLOOKUP($L$2,계약리스트!$A$2:$AD$10000,9,0),"#,##0")&" 원","") -> 26,400 원 | E21: 보증금 | F21: =IFERROR(TEXT(VLOOKUP($L$2,계약리스트!$A$2:$AD$10000,11,0),"#,##0")&" 원","") -> 300,000 원 | H21: 요금결제일 | I21: =IFERROR(IF(VLOOKUP($L$2,계약리스트!$A$2:$AD$10000,30,0)="","",VLOOKUP($L$2,계약리스트!$A$2:$AD$10000,30,0)),"") -> 월2회(15일, 말일)
B22: 납입방법 | C22: 계좌이체 | E22: 청구시작일 | F22: 차량 인도일부터
B23: 납입계좌 | C23: =IFERROR(IF(VLOOKUP($L$2,[1]계약리스트!$A$2:$AD$10000,24,0)="","",VLOOKUP($L$2,[1]계약리스트!$A$2:$AD$10000,24,0)),"") -> 기업은행 929-028075-04-011 포어스바이크(유)
B25: ■ 회사 정보 (공급자)
B26: 상호 | C26: 한국모터사이클리스 유한회사 | E26: 사업자번호 | F26: 647-86-03800 | H26: 대표이사 | I26: 김현수
B27: 주소 | C27: 경기도 수원시 권선구 입북로59번길 15 | G27: 고객센터 | H27: 010-2730-7845
B29: ■ 주요 확인사항 (서명 전 필독)
B30: 1. 본 계약에 따른 모든 대금(할부금·보증금·부대비용 등)의 수납 및 세금계산서 발행 업무는 포어스바이크(유)가 대행하며, 타 계좌 입금 시 입금 확인이 불가합니다.
B31: 2. 계약 취소·중도 해지 시 보증금은 반환되지 아니하며, 위약금과는 별도로 회수비용(출장비·운송비·원상복구비)은 계약자가 부담합니다.
B32: 3. 보증금 지급 유예 기간 내 미지급으로 계약이 자동 해지되는 경우, 계약자는 차량 반환과 동시에 (1) 인도일부터 반환일까지의 일할 사용료, (2) 감가손실액, (3) 등록비·번호판·보험료 등 회사가 이미 지출한 부대비용을 배상합니다.
B33: 4. 배달통·슬라이더 등 무상 지원 비품은 계약 취소·중도 해지 시 안내 장소로 반납하여야 합니다.
B34: 5. 세금계산서는 회사 명의로 발행되며, 본 계약서에 기재된 연대보증인(사업장)의 사업자등록번호를 기준으로 발급됩니다.
B36: ■ 개인(신용)정보 수집·이용, 금융거래정보 제공, 업무위탁 동의
B37: 수집·이용 목적 | D37: 거래관계 설정·유지, 상품 제공, 법령상 의무이행, 분쟁처리, 민원처리, 차량 분실 방지, 사고 대응, 서비스 개선, 통계 분석 등 계약 이행 전반
B38: 수집 항목 | D38: 성명(실명), 주민등록번호, 휴대전화번호, 이메일, 현주소, 근무지, 신분증 정보, 거래카드·계좌 정보, 차량 위치정보(FMS 수집 포함)
B39: 보유·이용 기간 | D39: 수집·이용 목적 달성 후 파기. 단, 전자상거래법 등 관련 법령에 따라 계약·결제 기록은 5년 보존, 불량이용자 재가입 방지 등 목적 기록은 해지 후 1년 보존
B40: 금융거래정보 제공 | D40: 신용카드·자동이체 등록·해지 시까지 수납기관(및 결제대행사)에 거래정보 제공 (금융실명법에 따라 동의)
B41: 자동이체 동의 | D41: 매월 발생하는 이륜차 임대료, 보증금, 위약금, 과태료, 범칙금 등을 신용카드 자동승인 또는 계좌 자동이체로 출금 거래 신청
B42: 업무위탁 내역 | D42: 협력사(공급·운송·출고 정보), 수납대행사 포어스바이크(유)(대금 수납·세금계산서·채권관리), 배달대행사(고객정보), 차량등록소(등록 사무), 효성에프엠에스(자동이체)
B43: 상기 "개인(신용)정보 수집·이용·제공 동의", "금융거래정보 제공 동의", "업무위탁 동의"에 대하여 □ 동의안함 □ 전부 동의함
B45: ■ 계약 체결
B46: 본인은 본 이륜차 할부판매 계약서와 별지 이용약관의 내용을 전부 설명 듣고 확인하였으며, 본 계약에 따른 권리·의무와 제반 동의 사항에 이의 없이 동의합니다.
B47: 계약자 | C47: =IFERROR(IF(VLOOKUP($L$2,계약리스트!$A$2:$AD$10000,12,0)="","",VLOOKUP($L$2,계약리스트!$A$2:$AD$10000,12,0)),"") -> 중앙 오토바이 가수점 | F47: (인) | G47: 연대보증인 | H47: =IFERROR(IF(VLOOKUP($L$2,계약리스트!$A$2:$AD$10000,14,0)="","",VLOOKUP($L$2,계약리스트!$A$2:$AD$10000,14,0)),"") -> 안종식 | J47: (인)
B48: 공급자 | C48: 한국모터사이클리스 유한회사 | J48: (인)

Sheet 이용약관
B1: 이륜차 할부판매 계약 이용약관
B3: 제1조 (목적) | D3: ② 결제방법이란, 회사가 안내한 수납대행사 은행계좌로 한국은행 발행 통화를 지급하거나 결제 수
B4: 이 약관은 한국모터사이클리스 유한회사(이하 "회사")와 본 계약을 체결한 계약자(이하 "계약자")간 | D4: 단을 통해 납부하는 것을 의미한다.
B5: 의 이륜차 할부판매에 관한 권리·의무를 규정함을 목적으로 한다. | D5: ③ 매도인의 가격 인상, 정부 정책 등 불가피한 사정으로 할부금이 변동될 경우 회사는 계약자에게 개
D6: 별 통지하며, 계약자는 이륜차 출고 이전까지 계약을 취소할 수 있다.
B7: 제2조 (용어의 정의) | D7: ④ 이륜차의 도난·멸실·훼손으로 운행이 불가능한 사유가 발생하더라도 계약자는 할부금 지급 의무를
B8: ① "할부판매 계약"이란, 계약자가 요청한 기종의 이륜차를 회사가 판매하고 계약자가 그 대금을 일 | D8: 거부할 수 없다.
B9: 일정 기간에 걸쳐 분할 지급하는 매매계약을 말한다. | D9: ⑤ 납부주기 변경으로 할부금이 조정되는 경우 최초 계약 당시의 단가표 기준에 따라 산정·적용한다.
B10: ② "이륜차"란, 회사가 계약자의 요청에 따라 본 계약서에 특정한 이륜차를 말하며, 인도 시 부착된 | D10: ⑥ 회사는 연체된 할부금·위약금 등 본 계약상 채권의 회수 및 추심 업무를 수납대행사(포어스바이크
B11: 부속품 및 장착물을 포함한다. | D11: 바이크 유한회사)에 위임하며, 미수금이 14일 이상 지속되는 경우 수납대행사는 회사를 대리하여
B12: ③ "계약기간"이란, 계약자가 본 계약에 따라 이륜차를 인도받아 사용하는 기간을 말한다. | D12: 계약자에게 독촉·추심할 수 있다.
B13: ④ "보증금"이란, 할부금 지급 및 본 계약상 채무이행을 담보하기 위해 계약자가 회사에 납부하는 금
B14: 원을 말하며, 계약기간 만료 시 계약자가 모든 채무를 이행 완료한 경우 반환한다. | D14: 제8조 (지연손해금 및 반환지연금)
B15: ⑤ "계약자"는 본 계약 제1면에 "계약자"로 기재된 사업장을 말하며, 본 계약상 주채무자이다. | D15: ① 계약자가 약정 금액을 기한 내에 이행하지 않는 경우 위약금이 발생하며, 계약자는 회사의 청구일
B16: ⑥ "연대보증인"은 본 계약 1면에 기재된 사업장 및 그 대표자를 말하며, 계약자와 연대하여 본 계약 | D16: 청구일로부터 5일 이내에 지급하여야 한다.
B17: 상 채무를 부담함과 동시에 세금계산서 수취 대상을 겸한다. | D17: ② 지연손해금 계산식: 지연손해금 = 연체금액 × 경과일수 × 연 20%
B18: ⑦ "위약금"이란, 계약자의 귀책사유로 주문 취소 또는 중도 해지 시 회사에 지급하여야 하는 금액을 | D18: ③ 반환지연금은 계약 만료·해지에도 불구하고 계약자가 이륜차를 반환하지 않고 점유·사용을 계속
B19: 말한다. | D19: 계속하는 경우 발생하며, 계산식은 다음과 같다. ㆍ반환지연금 = 1일 사용료 × 경과일수 × 연20%
B20: ⑧ "지연손해금"이란, 계약자가 할부금·위약금·과태료 등의 납부를 지체한 경우 발생하는 추가 비용 | D20: ④ 지연손해금과 반환지연금은 회사의 손해배상청구와 별도로 부과될 수 있다.
B21: 을 말한다. | D21: ⑤ 연체·미납이 발생하는 경우 회사는 계약자의 별도 동의 없이 해당 채무를 신용정보집중기관
B22: ⑨ "계약이관"이란, 계약자가 본 계약상의 권리와 의무를 제3자에게 승계하는 것을 말한다. | D22: 에 등록하거나 신용정보업체에 채권추심을 의뢰할 수 있다.
B23: ⑩ "사용자"는 본 계약 차량을 실제 운행하는 자로서, 계약자 본인 또는 계약자가 지정·관리하는 자를
B24: 말한다. | D24: 제9조 (연대보증인의 책임)
D25: ① 연대보증인(사업장 및 대표자)은 할부금 지급채무를 포함하여 계약자가 회사에 대하여 본 계약과
B26: 제3조 (서류 제출 및 이륜차 인도) | D26: 관련하여 부담하는 일체의 채무를 보증하며, 계약자 및 상호 간에 연대하여 그 채무를 이행한다.
B27: ① 계약자는 본 계약 체결에 필요한 서류를 회사에 제출하여야 하며, 보완 요구에도 성실히 응한다. | D27: ② 계약자가 회사의 동의 없이 본 계약상 채무를 제3자에게 인수·승계시킨 경우에도 연대보증인은
B28: 제출된 서류는 어떠한 경우에도 반환하지 아니한다. | D28: 채무가 전액 변제될 때까지 보증채무를 부담한다.
B29: ② 회사는 청구시작일부터 지정 장소에 이륜차를 인도하며, 해당 날짜부터 계약이 개시된다. 인도 이 | D29: ③ 연대보증인은 계약자의 미변제 채무가 남아 있는 경우 계약자의 채무를 회사보다 먼저 변제받을
B30: 후에는 계약자는 이륜차의 하자·결함을 이유로 할부금 지급의무를 거부할 수 없다. | D30: 받을 권리를 행사할 수 없다.
D31: ④ 보험 연령 변경 등 일부 계약 내용이 변경되는 경우 연대보증인이 별도로 서명·날인하지 않더라도
B32: 제4조 (소유권 유보 및 이전) | D32: 더라도 그 변경에 동의한 것으로 본다. 단, 변경 내용이 연대보증인에게 불리한 경우 계약자는 즉
B33: ① 본 계약에 따른 이륜차의 소유권은 계약자가 모든 채무를 전액 이행할 때까지 회사에 유보된다. | D33: 시 연대보증인에게 통지하여야 하며, 14일 이내 이의 제기 시 회사는 새로운 보증인의 추가 또는
B34: ② 인수형 계약의 경우, 계약자가 모든 채무를 완전히 이행한 때 회사는 회사의 내부 행정 절차에 따라 | D34: 교체를 요구할 수 있다. 연대보증인은 미성년자·배우자 등 불법 강제보증인으로 할 수 없다.
B35: 이륜차의 소유권을 계약자에게 이전한다.
B36: ③ 반납형 계약의 경우 이륜차의 소유권은 계약 종료 후에도 회사에 귀속된다. | D36: 제10조 (운행자성 및 운행지배)
B37: ④ 인수형 계약이라 하더라도 계약기간 만료 및 약정 금액의 완납 전에는 계약자는 이륜차의 소유권 | D37: ① 본 계약 차량의 소유권은 회사에 있으나, 회사는 자동차손해배상보장법 제3조에서 정한 "자기
B38: 을 주장할 수 없다. | D38: 기를 위하여 자동차를 운행하는 자"(이하 "운행자")에 해당하지 아니한다. 회사는 본 계약 차량에
D39: 대한 운행지배 및 운행이익을 갖지 아니한다.
B40: 제5조 (계약자의 책임) | D40: ② 본 계약 차량의 보험은 사용자(계약자 본인 또는 계약자가 지정한 자) 명의로 가입하며, 보
B41: ① 계약자는 선량한 관리자의 주의로 이륜차를 유지·관리하여야 하며, 운행 중 발생하는 모든 사고에 | D41: 험가입 주체는 사용자이다. 회사는 보험계약의 당사자가 아니다.
...
