Workbook

Sheet 계약리스트
A1: 계약번호 | B1: 계약일자 | C1: 차종 | D1: 차대번호 | E1: 차량번호 | F1: 색상 | G1: 정비여부 | H1: 보험연령 | I1: 일사용료 | J1: 사용일수 | K1: 보증금 | L1: 사업장 업체명 | M1: 사업자번호 | N1: 대표자명 | O1: 업체주소 | P1: 사업장 연락처 | Q1: 사업장 이메일 | R1: 대표자 주민번호 | S1: 대표자 연락처 | T1: 대표자 주소 | U1: 계약유형 | V1: 상품유형 | W1: 납입방법 | X1: 납입계좌 | Y1: 요금결제일
A2: 1 | B2: 2026-04-24 | C2: UHR150 | D2: LWMTDKH95THJ00467 | E2: 1나88370 | F2: 화이트 | G2: 비포함 | H2: 만30세 | I2: 26400 | J2: 365 | K2: 300000 | L2: 중앙 오토바이 가수점 | M2: 737-55-00719 | N2: 안종식 | O2: 경기도 오산시 가장로 763, 1층 5,6호(가수동) | P2: 010-5813-7336 | Q2: jungang@example.com | R2: 820530-1046518 | S2: 010-5813-7336 | T2: 경기도 오산시 궐동로 77, 1층(궐동) | U2: 렌트 | V2: 인수형 | W2: 계좌이체 | X2: 기업은행 929-028075-04-011 포어스바이크(유) | Y2: 월2회(15일,말일)

Sheet 계약서
L1: 계약번호입력→
B2: 이륜차 종합렌트 계약서 | L2: 1
B3: 포어스바이크 유한회사 | F3: 계약번호 | I3: =IFERROR(TEXT($L$2,"0000"),"")
B5: ■ 차량 정보
B6: 차종 | C6: =IFERROR(IF(VLOOKUP($L$2,계약리스트!$A$2:$AD$10000,3,0)="","",VLOOKUP($L$2,계약리스트!$A$2:$AD$10000,3,0)),"") | E6: 차량번호 | F6: =IFERROR(IF(VLOOKUP($L$2,계약리스트!$A$2:$AD$10000,5,0)="","",VLOOKUP($L$2,계약리스트!$A$2:$AD$10000,5,0)),"") | H6: 색상 | I6: =IFERROR(IF(VLOOKUP($L$2,계약리스트!$A$2:$AD$10000,6,0)="","",VLOOKUP($L$2,계약리스트!$A$2:$AD$10000,6,0)),"")
B7: 차대번호 | C7: =IFERROR(IF(VLOOKUP($L$2,계약리스트!$A$2:$AD$10000,4,0)="","",VLOOKUP($L$2,계약리스트!$A$2:$AD$10000,4,0)),"") | E7: 정비여부 | F7: =IFERROR(IF(VLOOKUP($L$2,계약리스트!$A$2:$AD$10000,7,0)="","",VLOOKUP($L$2,계약리스트!$A$2:$AD$10000,7,0)),"") | H7: 계약일자 | I7: =IFERROR(IF(VLOOKUP($L$2,계약리스트!$A$2:$AD$10000,2,0)="","",VLOOKUP($L$2,계약리스트!$A$2:$AD$10000,2,0)),"")
B8: 보험연령 | C8: =IFERROR(IF(VLOOKUP($L$2,계약리스트!$A$2:$AD$10000,8,0)="","",VLOOKUP($L$2,계약리스트!$A$2:$AD$10000,8,0)),"") | E8: ※ 본 차량은 위 보험연령 이상의 운전자만 운행 가능. 미달자 운전 사고 시 발생하는 모든 손해·구상금은 계약자가 전적으로 책임집니다.
B10: ■ 계약자
B11: 업체명 | C11: =IFERROR(IF(VLOOKUP($L$2,[1]계약리스트!$A$2:$AD$10000,14,0)="","",VLOOKUP($L$2,[1]계약리스트!$A$2:$AD$10000,14,0)),"") | E11: 주민등록번호 | F11: =IFERROR(IF(VLOOKUP($L$2,[1]계약리스트!$A$2:$AD$10000,18,0)="","",VLOOKUP($L$2,[1]계약리스트!$A$2:$AD$10000,18,0)),"") | H11: 연락처 | I11: =IFERROR(IF(VLOOKUP($L$2,[1]계약리스트!$A$2:$AD$10000,19,0)="","",VLOOKUP($L$2,[1]계약리스트!$A$2:$AD$10000,19,0)),"")
B12: 연락처 | C12: =IFERROR(IF(VLOOKUP($L$2,[1]계약리스트!$A$2:$AD$10000,16,0)="","",VLOOKUP($L$2,[1]계약리스트!$A$2:$AD$10000,16,0)),"") | E12: 업체주소 | F12: =IFERROR(IF(VLOOKUP($L$2,[1]계약리스트!$A$2:$AD$10000,15,0)="","",VLOOKUP($L$2,[1]계약리스트!$A$2:$AD$10000,15,0)),"")
B13: ※ 제출 서류 : 사업자등록증 사본, 대표자 신분증 사본
B15: ■ 연대보증인
B16: 업체명 | C16: =IFERROR(IF(VLOOKUP($L$2,[1]계약리스트!$A$2:$AD$10000,12,0)="","",VLOOKUP($L$2,[1]계약리스트!$A$2:$AD$10000,12,0)),"") | E16: 사업자번호 | F16: =IFERROR(IF(VLOOKUP($L$2,[1]계약리스트!$A$2:$AD$10000,13,0)="","",VLOOKUP($L$2,[1]계약리스트!$A$2:$AD$10000,13,0)),"") | H16: 대표자명 | I16: =IFERROR(IF(VLOOKUP($L$2,[1]계약리스트!$A$2:$AD$10000,14,0)="","",VLOOKUP($L$2,[1]계약리스트!$A$2:$AD$10000,14,0)),"")
B17: 주소 | C17: =IFERROR(IF(VLOOKUP($L$2,[1]계약리스트!$A$2:$AD$10000,20,0)="","",VLOOKUP($L$2,[1]계약리스트!$A$2:$AD$10000,20,0)),"")
B18: ※ 제출 서류 : 대표자 신분증 사본 | 보증 기한 : 2년 | 보증 한도 : 전체 이용료의 130%
B20: ■ 계약 조건
B21: 계약유형 | C21: =IFERROR(IF(VLOOKUP($L$2,[2]계약리스트!$A$2:$AD$10000,21,0)="","",VLOOKUP($L$2,[2]계약리스트!$A$2:$AD$10000,21,0)),"") | E21: 상품유형 | F21: =IFERROR(IF(VLOOKUP($L$2,[2]계약리스트!$A$2:$AD$10000,22,0)="","",VLOOKUP($L$2,[2]계약리스트!$A$2:$AD$10000,22,0)),"") | H21: 렌트 기간 | I21: =IFERROR(VLOOKUP($L$2,[2]계약리스트!$A$2:$AD$10000,10,0)&"일","")
B22: 일사용료 (VAT포함) | C22: =IFERROR(TEXT(VLOOKUP($L$2,[2]계약리스트!$A$2:$AD$10000,9,0),"#,##0")&" 원","") | E22: 보증금 | F22: =IFERROR(TEXT(VLOOKUP($L$2,[2]계약리스트!$A$2:$AD$10000,11,0),"#,##0")&" 원","") | H22: 요금결제일 | I22: =IFERROR(IF(VLOOKUP($L$2,[2]계약리스트!$A$2:$AD$10000,25,0)="","",VLOOKUP($L$2,[2]계약리스트!$A$2:$AD$10000,25,0)),"")
B23: 납입방법 | C23: =IFERROR(IF(VLOOKUP($L$2,[2]계약리스트!$A$2:$AD$10000,23,0)="","",VLOOKUP($L$2,[2]계약리스트!$A$2:$AD$10000,23,0)),"") | E23: 청구시작일 | F23: =TEXT(_xlfn.XLOOKUP(L2,[2]계약리스트!A:A,[2]계약리스트!B:B), "yyyy년 mm월 dd일")
B24: 납입계좌 | C24: =IFERROR(IF(VLOOKUP($L$2,[2]계약리스트!$A$2:$AD$10000,24,0)="","",VLOOKUP($L$2,[2]계약리스트!$A$2:$AD$10000,24,0)),"")
B26: ■ 회사 정보
B27: 상호 | C27: 포어스바이크 유한회사 | E27: 사업자번호 | F27: 104-86-62883 | H27: 대표이사 | I27: 김현수
B28: 주소 | C28: 강원특별자치도 춘천시 춘천로 188, 210호, 211호-에이66호 | G28: 고객센터 | H28: 010-2730-7845
B30: ⚠ 주요 확인사항 (서명 전 필독)
B31: 운행자성 | D31: 회사는 본 차량의 소유자이나 자동차손해배상보장법상 "운행자"가 아니며, 운행자성(운행지배·운행이익)은 전적으로 계약자에게 있습니다. 따라서 운행 중 발생하는 모든 인적·물적 손해의 운행자 책임은 계약자가 부담합니다.
B32: 사고 즉시 고지 의무 | D32: 회사는 운행자가 아니므로 사고 발생 사실을 직접 인지할 수 없습니다. 사고(인적·물적 손해, 단독사고, 차량 파손, 도난, 멸실 등 일체) 발생 시 계약자는 즉시 회사에 고지하여야 하며, 미고지·지연 고지로 발생하는 모든 손해(보험 미보장분, 회사 추가 부담 비용 등)는 계약자가 전적으로 책임지며 회사는 본 계약을 즉시 해지하고 차량을 회수할 수 있습니다.
B33: 보험연령 미달자 운전 | D33: 본 차량은 보험연령 이상의 운전자만이 운행해야 합니다. 보험연령 미달자가 운행하여 발생한 사고·손해·보험사 구상금은 회사의 라이더 신원·연령 확인 여부와 관계없이 계약자가 전적으로 책임집니다.
B34: 12대 중과실·면책사고 | D34: 신호위반·중앙선침범·무면허·음주운전 등 12대 중과실 또는 보험약관상 면책사항(고의·약물·범죄·운행자 범위 외 운전·도난중 운행 등)에 해당하는 사고로 회사에 보험사 구상금이 청구되는 경우, 계약자는 통보 후 7일 이내에 전액 변제하여야 합니다.
B35: 미변제 시 즉시 처리 | D35: 위 구상금을 7일 이내 변제하지 아니하는 경우 본 계약은 자동 해지되고, 회사는 차량을 즉시 회수하며, 보증금은 반환하지 아니합니다(위약금·손해배상금은 별도 청구).
B36: 계열사 미납 교차 적용 | D36: 계약자가 한국모터사이클리스 유한회사 또는 회사의 계열사와 체결한 다른 이륜차 계약에서 미수금이 7일 이상 지속되는 경우, 회사는 본 계약을 해지하고 본 차량을 회수할 수 있습니다.
B37: 보증금 처리 | D37: 계약 취소·중도 해지 시 보증금은 반환되지 않으며, 위약금 및 손해배상금은 별도로 청구됩니다.
B38: 수납 방식 | D38: 본 계약 모든 대금은 포어스바이크(유) 명의 계좌로 직접 입금되며, 타 계좌 입금 시 수납이 확인되지 않을 수 있습니다.
B40: ■ 개인(신용)정보 수집·이용, 금융거래정보 제공, 업무위탁 동의
B41: 수집·이용 목적 | D41: 거래관계 설정·유지, 상품 제공, 법령상 의무이행, 분쟁처리, 차량 분실 방지, 사고 대응, 보험사고 처리, 채권 관리 등 계약 이행 전반
B42: 수집 항목 | D42: 사업장 상호·사업자번호·주소·연락처·이메일, 대표자 성명·주민등록번호·휴대전화번호·주소, 거래계좌 정보, 차량 위치정보(FMS 수집 포함)
B43: 보유·이용 기간 | D43: 수집 목적 달성 후 파기. 단, 전자상거래법 등 관련 법령에 따라 계약·결제 기록 5년, 불량이용자 재가입 방지 기록 해지 후 1년 보존
B44: 금융거래정보 제공 | D44: 신용카드·자동이체 등록·해지 시까지 회사 및 결제대행사에 거래정보 제공 (금융실명법에 따라 동의)
B45: 자동이체 동의 | D45: 매월 발생하는 렌트료, 보증금, 위약금, 과태료, 범칙금, 보험사 구상금 등을 신용카드 자동승인 또는 계좌 자동이체로 출금 거래 신청
B46: 업무위탁 내역 | D46: 협력사(공급·운송·출고 정보), 배달대행사(고객정보), 차량등록소(등록 사무), 효성에프엠에스(자동이체)
B47: 상기 "개인(신용)정보 수집·이용·제공 동의", "금융거래정보 제공 동의", "업무위탁 동의"에 대하여 □ 동의안함 □ 전부 동의함
...

Sheet 이용약관
B1: 이륜차 종합렌트 계약 이용약관
B3: 제1조 (목적) | D3: 제8조 (연대보증인의 책임)
B4: 이 약관은 포어스바이크 유한회사(이하 "회사")와 본 계약을 체결한 계약자간의 이륜차 렌트에 관 | D4: ① 본 계약에 연대보증인이 지정된 경우, 연대보증인은 렌트료 지급채무를 포함하여 계약자가 회사
B5: 한 권리·의무를 규정함을 목적으로 한다. | D5: 에 부담하는 일체의 채무를 보증하며, 계약자와 연대하여 그 채무를 이행한다.
D6: ② 계약자가 회사 동의 없이 본 계약상 채무를 제3자에게 인수·승계시킨 경우에도 연대보증인은 채무
B7: 제2조 (용어의 정의) | D7: 가 전액 변제될 때까지 보증채무를 부담한다.
B8: ① "이륜차 렌트 계약"이란, 회사가 계약자의 요청에 따라 이륜차를 취득하여 일정 기간 사용하게 | D8: ③ 연대보증인은 계약자의 미변제 채무가 남아있는 경우 계약자의 채무를 회사보다 먼저 변제받을
B9: 하고 그 대가를 정기적으로 지급받는 계약을 말한다. | D9: 권리를 행사할 수 없다.
B10: ② "이륜차"란, 회사가 본 계약서에 특정한 이륜차로서 인도 시 부착된 부속품·장착물을 포함한다. | D10: ④ 보험연령 변경 등 일부 계약 내용 변경 시 연대보증인이 별도 서명·날인하지 않더라도 동의한 것
B11: ③ "계약기간"이란, 계약자가 본 계약에 따라 이륜차를 인도받아 사용하는 기간을 말한다. | D11: 으로 본다. 변경 내용이 연대보증인에게 불리한 경우 계약자는 즉시 통지하여야 하며, 14일 이내 이
B12: ④ "보증금"이란, 렌트료 등 본 계약상 채무이행을 담보하기 위해 계약자가 회사에 납부하는 금원 | D12: 의 제기 시 회사는 새 보증인의 추가·교체를 요구할 수 있다.
B13: 을 말하며, 계약기간 만료 및 모든 채무 이행 완료 시 반환한다.
B14: ⑤ "계약자"는 본 계약 1면에 "계약자"로 기재된 라이더 본인을 말하며, 본 계약상 주채무자이자 본 계약 차량을 실제 운행하는 자이다. | D14: 제9조 (보험계약의 체결 및 관리)
B15: ⑥ "연대보증인"은 본 계약 1면에 기재된 사업장 및 그 대표자를 말하며, 계약자와 연대하여 본 | D15: ① 회사는 이륜차 출고 시 계약자가 요청하는 보험연령에 따라 종합보험(대인배상Ⅰ·대인배상Ⅱ·대
B16: 계약상 채무를 부담함과 동시에 세금계산서 수취 대상을 겸한다. 연대보증인은 별도로 지정될 수 | D16: 물배상)에 가입한다. 다만, 자기신체사고·자기차량손해는 가입하지 아니한다. 회사는 계약자를 대
B17: 있으며, 지정되지 않은 경우 본 약관의 연대보증인 관련 조항은 적용되지 아니한다. | D17: 신하여 보험료를 납부하며, 보험의 내용은 보험증권 약관에 따른다.
B18: ⑦ "계약이관"이란, 계약자가 본 계약상의 권리와 의무를 제3자에게 승계하는 것을 말한다. | D18: ② 렌트료·과태료 등 미수금이 있을 경우 보험연령 변경이 불가하다. 보험사 정책상 보험 연령 변
D19: 경이 불가능한 경우 회사는 계약자에게 즉시 통지한다.
D20: ③ 보험연령 변경에 따라 렌트료가 변경될 경우 해당 차량 최초 계약 당시 단가표 기준으로 적용
B21: ⑧ "보험연령"이란, 본 계약 차량에 가입된 보험에서 운전자로서 보장 가능한 최저연령을 말하며, | D21: 된다. 보험사 정책상 고가의 보험료를 수취하는 경우 보험사 보험료 정책에 따라 고가의 렌트료가
B22: 본 계약 1면에 기재된 만 나이를 의미한다. | D22: 적용될 수 있다.
B23: ⑨ "위약금"이란, 계약자의 귀책사유로 주문 취소 또는 중도 해지 시 회사에 지급하여야 하는 금액 | D23: ④ 계약 해지 사유 발생 시 회사는 보험을 해지할 수 있으며, 이로 인해 발생하는 보험환급금은
B24: 을 말한다. | D24: 회사에 귀속되고 계약자는 이에 대한 추가 환급을 청구할 수 없다.
B25: ⑩ "지연손해금"이란, 계약자가 렌트료·위약금·과태료 등의 납부를 지체한 경우 발생하는 추가 비 | D25: ⑤ 회사는 계약기간과 일치하게 보험계약을 체결한다. 계약 종료일 이후 무보험 상태에서 운행하여
B26: 용을 말한다. | D26: 손해가 발생하면 계약자가 배상책임 및 민·형사상 책임을 진다.
B27: ⑪ "구상금"이란, 본 계약 차량 운행 중 발생한 사고로 보험사가 회사에게 청구한 금액 일체를 말한다.
B28: ⑫ "책임보험"이란, 자동차손해배상보장법에 따른 의무보험으로서 대인배상Ⅰ과 대물배상을 보장 | D28: 제10조 (운행자성 및 운행지배)
B29: 하는 보험을 말한다. | D29: ① 본 계약 차량의 소유권은 회사에 있으나, 회사는 자동차손해배상보장법 제3조에서 정한 "자기를
B30: ⑬ "종합보험"이란, 책임보험에 대인배상Ⅱ를 추가로 담보하는 보험을 말한다. | D30: 위하여 자동차를 운행하는 자"(이하 "운행자")에 해당하지 아니한다. 회사는 본 계약 차량에 대한 운
D31: 행지배 및 운행이익을 갖지 아니한다.
B32: 제3조 (서류 제출 및 이륜차 인도) | D32: ② 본 계약 차량의 운행자는 계약자이며, 운행 중 발생하는 모든 인적·물적 손해에 대한 운행자 책
B33: ① 계약자는 본 계약 체결에 필요한 서류를 회사에 제출하여야 하며, 보완 요구에도 성실히 응한다. | D33: 임은 전적으로 계약자가 부담한다. 계약자가 제3자에게 차량을 운행하게 한 경우에도 운행자성은
B34: 제출된 서류는 어떠한 경우에도 반환하지 아니한다. | D34: 여전히 계약자에게 있다.
B35: ② 회사는 청구시작일부터 지정 장소에 이륜차를 인도하며, 해당 날짜부터 계약이 개시된다. 인도 | D35: ③ 제3자가 회사를 상대로 운행자 책임을 청구하는 경우 계약자는 자신의 비용·책임으로 회사를 면
B36: 이후에는 계약자는 이륜차의 하자·결함을 이유로 렌트료 지급의무를 거부할 수 없다. | D36: 책시켜야 하며, 회사가 부득이 배상한 경우 그 금액·관련 비용 일체를 즉시 회사에 상환하여야 한다.
B38: 제4조 (소유권 유보 및 이전) | D38: 제11조 (사고 발생 시 고지 의무)
B39: ① 본 계약에 따른 이륜차의 소유권은 계약자가 모든 채무를 전액 이행할 때까지 회사에 유보된다. | D39: ① 회사는 본 계약 차량의 운행자가 아니므로 사고 발생 사실을 직접 인지할 수 없다. 따라서 본 조
B40: ② 인수형 계약의 경우, 계약자가 모든 채무를 완전히 이행한 때 회사는 회사의 내부 행정 절차에 | D40: 의 고지 의무는 본 계약상 계약자의 핵심 의무에 해당한다.
B41: 따라 이륜차의 소유권을 계약자에게 이전한다. | D41: ② 다음 사유 발생 시 계약자는 즉시 회사에 고지하여야 한다: 인적·물적
B42: ③ 반납형 계약의 경우 이륜차의 소유권은 계약 종료 후에도 회사에 귀속된다. | D42: 손해 사고, 단독사고·차량 파손, 도난·멸실·분실, 보험사 접수 필요 사건, 무면허·음주·약물·범죄 목
...
