Workbook

Sheet 계약리스트
A1: 계약번호 | B1: 계약일자 | C1: 차종 | D1: 차대번호 | E1: 차량번호 | F1: 색상 | G1: 정비여부 | H1: 보험연령 | I1: 일사용료 | J1: 사용일수 | K1: 보증금 | L1: 사업장 업체명 | M1: 사업자번호 | N1: 대표자명 | O1: 업체주소 | P1: 사업장 연락처 | Q1: 사업장 이메일 | R1: 대표자 주민번호 | S1: 대표자 연락처 | T1: 대표자 주소 | U1: 계약유형 | V1: 상품유형 | W1: 납입방법 | X1: 납입계좌 | Y1: 요금결제일
A2: 1 | B2: 2026-04-24 | C2: UHR150 | D2: LWMTDKH95THJ00467 | E2: 1나88370 | F2: 화이트 | G2: 비포함 | H2: 만30세 | I2: 26400 | J2: 365 | K2: 300000 | L2: 중앙 오토바이 가수점 | M2: 737-55-00719 | N2: 안종식 | O2: 경기도 오산시 가장로 763, 1층 5,6호(가수동) | P2: 010-5813-7336 | Q2: jungang@example.com | R2: 820530-1046518 | S2: 010-5813-7336 | T2: 경기도 오산시 궐동로 77, 1층(궐동) | U2: 렌트 | V2: 인수형 | W2: 계좌이체 | X2: 기업은행 929-028075-04-011 포어스바이크(유) | Y2: 월2회(15일,말일)

Sheet 계약서
L1: 계약번호입력→
B2: 이륜차 렌트 계약서 | L2: 1
B3: 포어스바이크 유한회사 | F3: 계약번호 | I3: =IFERROR(TEXT($L$2,"0000"),"") -> 0001
B5: ■ 차량 정보
B6: 차종 | C6: =IFERROR(IF(VLOOKUP($L$2,계약리스트!$A$2:$AD$10000,3,0)="","",VLOOKUP($L$2,계약리스트!$A$2:$AD$10000,3,0)),"") -> UHR150 | E6: 차량번호 | F6: =IFERROR(IF(VLOOKUP($L$2,계약리스트!$A$2:$AD$10000,5,0)="","",VLOOKUP($L$2,계약리스트!$A$2:$AD$10000,5,0)),"") -> 1나88370 | H6: 색상 | I6: =IFERROR(IF(VLOOKUP($L$2,계약리스트!$A$2:$AD$10000,6,0)="","",VLOOKUP($L$2,계약리스트!$A$2:$AD$10000,6,0)),"") -> 화이트
B7: 차대번호 | C7: =IFERROR(IF(VLOOKUP($L$2,계약리스트!$A$2:$AD$10000,4,0)="","",VLOOKUP($L$2,계약리스트!$A$2:$AD$10000,4,0)),"") -> LWMTDKH95THJ00467 | E7: 정비여부 | F7: =IFERROR(IF(VLOOKUP($L$2,계약리스트!$A$2:$AD$10000,7,0)="","",VLOOKUP($L$2,계약리스트!$A$2:$AD$10000,7,0)),"") -> 비포함 | H7: 계약일자 | I7: =IFERROR(IF(VLOOKUP($L$2,계약리스트!$A$2:$AD$10000,2,0)="","",VLOOKUP($L$2,계약리스트!$A$2:$AD$10000,2,0)),"") -> 2026-04-24
B8: 보험연령 | C8: =IFERROR(IF(VLOOKUP($L$2,계약리스트!$A$2:$AD$10000,8,0)="","",VLOOKUP($L$2,계약리스트!$A$2:$AD$10000,8,0)),"") -> 만30세 | E8: ※ 본 차량은 위 보험연령 이상의 운전자만 운행 가능. 미달자 운전 사고 시 발생하는 모든 손해·구상금은 계약자가 전적으로 책임집니다.
B10: ■ 계약자
B11: 업체명 | C11: =IFERROR(IF(VLOOKUP($L$2,계약리스트!$A$2:$AD$10000,12,0)="","",VLOOKUP($L$2,계약리스트!$A$2:$AD$10000,12,0)),"") -> 중앙 오토바이 가수점 | E11: 사업자번호 | F11: =IFERROR(IF(VLOOKUP($L$2,계약리스트!$A$2:$AD$10000,13,0)="","",VLOOKUP($L$2,계약리스트!$A$2:$AD$10000,13,0)),"") -> 737-55-00719 | H11: 대표자명 | I11: =IFERROR(IF(VLOOKUP($L$2,계약리스트!$A$2:$AD$10000,14,0)="","",VLOOKUP($L$2,계약리스트!$A$2:$AD$10000,14,0)),"") -> 안종식
B12: 연락처 | C12: =IFERROR(IF(VLOOKUP($L$2,계약리스트!$A$2:$AD$10000,16,0)="","",VLOOKUP($L$2,계약리스트!$A$2:$AD$10000,16,0)),"") -> 010-5813-7336 | E12: 업체주소 | F12: =IFERROR(IF(VLOOKUP($L$2,계약리스트!$A$2:$AD$10000,15,0)="","",VLOOKUP($L$2,계약리스트!$A$2:$AD$10000,15,0)),"") -> 경기도 오산시 가장로 763, 1층 5,6호(가수동)
B13: ※ 제출 서류 : 사업자등록증 사본, 대표자 신분증 사본
B15: ■ 연대보증인
B16: 성명 | C16: =IFERROR(IF(VLOOKUP($L$2,계약리스트!$A$2:$AD$10000,14,0)="","",VLOOKUP($L$2,계약리스트!$A$2:$AD$10000,14,0)),"") -> 안종식 | E16: 주민등록번호 | F16: =IFERROR(IF(VLOOKUP($L$2,계약리스트!$A$2:$AD$10000,18,0)="","",VLOOKUP($L$2,계약리스트!$A$2:$AD$10000,18,0)),"") -> 820530-1046518 | H16: 연락처 | I16: =IFERROR(IF(VLOOKUP($L$2,계약리스트!$A$2:$AD$10000,19,0)="","",VLOOKUP($L$2,계약리스트!$A$2:$AD$10000,19,0)),"") -> 010-5813-7336
B17: 주소 | C17: =IFERROR(IF(VLOOKUP($L$2,계약리스트!$A$2:$AD$10000,20,0)="","",VLOOKUP($L$2,계약리스트!$A$2:$AD$10000,20,0)),"") -> 경기도 오산시 궐동로 77, 1층(궐동)
B18: ※ 제출 서류 : 대표자 신분증 사본 | 보증 기한 : 2년 | 보증 한도 : 전체 이용료의 130%
B20: ■ 계약 조건
B21: 계약유형 | C21: =IFERROR(IF(VLOOKUP($L$2,계약리스트!$A$2:$AD$10000,21,0)="","",VLOOKUP($L$2,계약리스트!$A$2:$AD$10000,21,0)),"") -> 렌트 | E21: 상품유형 | F21: =IFERROR(IF(VLOOKUP($L$2,계약리스트!$A$2:$AD$10000,22,0)="","",VLOOKUP($L$2,계약리스트!$A$2:$AD$10000,22,0)),"") -> 인수형 | H21: 렌탈 기간 | I21: =IFERROR(VLOOKUP($L$2,계약리스트!$A$2:$AD$10000,10,0)&"일","") -> 365일
B22: 일사용료 (VAT포함) | C22: =IFERROR(TEXT(VLOOKUP($L$2,계약리스트!$A$2:$AD$10000,9,0),"#,##0")&" 원","") -> 26,400 원 | E22: 보증금 | F22: =IFERROR(TEXT(VLOOKUP($L$2,계약리스트!$A$2:$AD$10000,11,0),"#,##0")&" 원","") -> 300,000 원 | H22: 요금결제일 | I22: =IFERROR(IF(VLOOKUP($L$2,계약리스트!$A$2:$AD$10000,25,0)="","",VLOOKUP($L$2,계약리스트!$A$2:$AD$10000,25,0)),"") -> 월2회(15일,말일)
B23: 납입방법 | C23: =IFERROR(IF(VLOOKUP($L$2,계약리스트!$A$2:$AD$10000,23,0)="","",VLOOKUP($L$2,계약리스트!$A$2:$AD$10000,23,0)),"") -> 계좌이체 | E23: 청구시작일 | F23: 차량 인도일부터
B24: 납입계좌 | C24: =IFERROR(IF(VLOOKUP($L$2,계약리스트!$A$2:$AD$10000,24,0)="","",VLOOKUP($L$2,계약리스트!$A$2:$AD$10000,24,0)),"") -> 기업은행 929-028075-04-011 포어스바이크(유)
B26: ■ 회사 정보 (공급자 · 직접 수납)
B27: 상호 | C27: 포어스바이크 유한회사 | E27: 사업자번호 | F27: 104-86-62883 | H27: 대표이사 | I27: 김현수
B28: 주소 | C28: 강원특별자치도 춘천시 춘천로 188, 210호, 211호-에이66호 | G28: 고객센터 | H28: 010-2730-7845 / 0507-1489-7885
B30: ⚠ 주요 확인사항 (서명 전 필독)
B31: 운행자성 | D31: 회사는 본 차량의 소유자이나 자동차손해배상보장법상 "운행자"가 아니며, 운행자성(운행지배·운행이익)은 전적으로 계약자에게 있습니다. 따라서 운행 중 발생하는 모든 인적·물적 손해의 운행자 책임은 계약자가 부담합니다.
B32: 사고 즉시 고지 의무 | D32: 회사는 운행자가 아니므로 사고 발생 사실을 직접 인지할 수 없습니다. 사고(인적·물적 손해, 단독사고, 차량 파손, 도난, 멸실 등 일체) 발생 시 계약자는 즉시 회사에 고지하여야 하며, 미고지·지연 고지로 발생하는 모든 손해(보험 미보장분, 회사 추가 부담 비용 등)는 계약자가 전적으로 책임지며 회사는 본 계약을 즉시 해지하고 차량을 회수할 수 있습니다.
B33: 보험연령 미달자 운전 | D33: 본 차량은 보험연령 이상의 운전자만이 운행해야 합니다. 보험연령 미달자가 운행하여 발생한 사고·손해·보험사 구상금은 회사의 라이더 신원·연령 확인 여부와 관계없이 계약자가 전적으로 책임집니다.
B34: 12대 중과실·면책사고 | D34: 신호위반·중앙선침범·무면허·음주운전 등 12대 중과실 또는 보험약관상 면책사항(고의·약물·범죄·운행자 범위 외 운전·도난중 운행 등)에 해당하는 사고로 회사에 보험사 구상금이 청구되는 경우, 계약자는 통보 후 7일 이내에 전액 변제하여야 합니다.
B35: 미변제 시 즉시 처리 | D35: 위 구상금을 7일 이내 변제하지 아니하는 경우 본 계약은 자동 해지되고, 회사는 차량을 즉시 회수하며, 보증금은 반환하지 아니합니다(위약금·손해배상금은 별도 청구).
B36: 계열사 미납 교차 적용 | D36: 계약자가 한국모터사이클리스 유한회사 또는 회사의 계열사와 체결한 다른 이륜차 계약에서 미수금이 14일 이상 지속되는 경우, 회사는 본 계약을 해지하고 본 차량을 회수할 수 있습니다.
B37: 보증금 처리 | D37: 계약 취소·중도 해지 시 보증금은 반환되지 않으며, 위약금 및 손해배상금은 별도로 청구됩니다.
B38: 수납 방식 | D38: 본 계약 모든 대금은 포어스바이크(유) 명의 계좌로 직접 입금되며, 타 계좌 입금 시 수납이 확인되지 않을 수 있습니다.
B40: ■ 개인(신용)정보 수집·이용, 금융거래정보 제공, 업무위탁 동의
B41: 수집·이용 목적 | D41: 거래관계 설정·유지, 상품 제공, 법령상 의무이행, 분쟁처리, 차량 분실 방지, 사고 대응, 보험사고 처리, 채권 관리 등 계약 이행 전반
B42: 수집 항목 | D42: 사업장 상호·사업자번호·주소·연락처·이메일, 대표자 성명·주민등록번호·휴대전화번호·주소, 거래계좌 정보, 차량 위치정보(FMS 수집 포함)
B43: 보유·이용 기간 | D43: 수집 목적 달성 후 파기. 단, 전자상거래법 등 관련 법령에 따라 계약·결제 기록 5년, 불량이용자 재가입 방지 기록 해지 후 1년 보존
B44: 금융거래정보 제공 | D44: 신용카드·자동이체 등록·해지 시까지 회사 및 결제대행사에 거래정보 제공 (금융실명법에 따라 동의)
B45: 자동이체 동의 | D45: 매월 발생하는 렌탈료, 보증금, 위약금, 과태료, 범칙금, 보험사 구상금 등을 신용카드 자동승인 또는 계좌 자동이체로 출금 거래 신청
B46: 업무위탁 내역 | D46: 협력사(공급·운송·출고 정보), 배달대행사(고객정보), 차량등록소(등록 사무), 효성에프엠에스(자동이체)
B47: 상기 "개인(신용)정보 수집·이용·제공 동의", "금융거래정보 제공 동의", "업무위탁 동의"에 대하여 □ 동의안함 □ 전부 동의함
...

Sheet 이용약관
B1: [별지] 이륜차 종합렌탈 계약 이용약관
B3: 제1조 (목적) | D3: 제15조 (계약자 및 사용자의 책임)
B4: 이 약관은 포어스바이크 유한회사(이하 "회사")와 본 계약을 체결한 계약자(배달대행사) 간의 이륜차 종합렌탈에 관한 권리·의무를 규정함을 목적으로 한다. | D4: ① 계약자는 선량한 관리자의 주의로 이륜차를 유지·관리하여야 하며, 사용자(라이더)가 운행 중 발생하는 모든 사고에 대한 책임을 부담한다.
D5: ② 계약자는 계약 기간 중 임의로 다른 부착물을 장착하거나 이륜차의 구조를 변경할 수 없다.
B6: 제2조 (용어의 정의) | D6: ③ 이륜차의 소유권은 회사에 있으며, 계약자는 사용수익권과 운행이익권을 가진다. 본 계약이 해지된 경우 계약자는 즉시 운행을 중단하고 이륜차를 반환한다.
B7: ① "이륜차 렌탈 계약"이란, 회사가 계약자의 요청에 따라 이륜차를 취득하여 일정 기간 사용하게 하고 그 대가를 정기적으로 지급받는 계약을 말한다. | D7: ④ 계약자는 사용자(라이더)의 보험연령 충족, 면허 보유, 음주·약물 미복용 여부 등 운행 자격을 확인할 의무가 있으며, 이를 위반하여 발생한 사고로 인한 손해 일체는 계약자가 부담한다.
B8: ② "이륜차"란, 회사가 본 계약서에 특정한 이륜차로서 인도 시 부착된 부속품 및 장착물을 포함한다. | D8: ⑤ 제3자가 이륜차에 대하여 권리를 주장하거나 강제집행 등으로 회사의 소유권을 침해할 위험이 있는 경우 계약자는 회사의 소유임을 주장·입증하여 침해를 막고 즉시 회사에 통지하여야 한다.
B9: ③ "계약기간"이란, 계약자가 본 계약에 따라 이륜차를 인도받아 사용하는 기간을 말한다. | D9: ⑥ 계약자는 이륜차 인도일부터 반환일까지 도난·멸실·훼손 등 일체의 사고에 대한 책임을 부담한다. 도난·멸실·훼손 시 (1) 원상복구 또는 (2) 동일 모델·사양으로 교체 중 하나를 자신의 비용으로 이행한다.
B10: ④ "보증금"이란, 렌탈료 등 본 계약상 채무이행을 담보하기 위해 계약자가 회사에 납부하는 금원을 말하며, 계약기간 만료 및 모든 채무 이행 완료 시 반환한다.
B11: ⑤ "계약자"는 본 계약 제1면에 "계약자(배달대행사)"로 기재된 사업장(법인 또는 개인사업자)을 말하며, 본 계약상 모든 채무를 부담한다. | D11: 제16조 (계약의 이관 및 승계)
B12: ⑥ "연대보증인"은 본 계약 제1면에 기재된 계약자(사업장)의 대표자 개인을 말하며, 계약자와 연대하여 본 계약상 모든 채무를 부담한다. | D12: ① 계약자는 회사의 사전 승인 없이 본 계약상의 권리·의무를 제3자에게 승계할 수 없다.
B13: ⑦ "사용자(라이더)"는 계약자가 지정·관리하는 자로서 실제로 이륜차를 운행하는 자를 말한다. 계약자는 사용자(라이더)의 신원·자격·연령 관리에 대한 모든 책임을 부담하며, 회사는 사용자의 신원·연령을 사전에 확인할 의무가 없다. | D13: ② 계약자가 제3자에게 승계하고자 하는 경우 인적사항·신용상태·영업상황 등 필요 정보를 제공하여야 하며, 회사는 심사기준에 부합하지 않으면 거절할 수 있다.
B14: ⑧ "보험연령"이란, 본 계약 차량에 가입된 보험에서 운전자로서 보장 가능한 최저연령을 말하며, 본 계약 제1면에 기재된 만 나이를 의미한다. | D14: ③ 회사의 승인 없이 계약자가 제3자에게 넘긴 경우, 계약자는 렌탈료 지급의무 및 기타 채무를 계속 이행하여야 한다.
B15: ⑨ "위약금"이란, 계약자의 귀책사유로 주문 취소 또는 중도 해지 시 회사에 지급하여야 하는 금액을 말한다. | D15: ④ 계약이관을 하기 위해서는 렌탈료·수리비·위약금·과태료·구상금 등 일체의 미납금이 없어야 한다.
B16: ⑩ "지연손해금"이란, 계약자가 렌탈료·위약금·과태료 등의 납부를 지체한 경우 발생하는 추가 비용을 말한다. | D16: ⑤ 승계받고자 하는 제3자가 계약이관서에 서명함으로써 절차는 완료된 것으로 본다.
B17: ⑪ "구상금"이란, 본 계약 차량 운행 중 발생한 사고로 보험사가 회사에게 청구한 금액 일체를 말한다.
D18: 제17조 (차량 위치정보 등 제공 동의)
B19: 제3조 (서류 제출 및 보완) | D19: ① 본 차량에는 도난·멸실·분실 위험 방지를 위해 위치정보 수집 장치가 부착되어 있으며, 계약자는 이를 인지하고 동의한다.
B20: ① 계약자는 본 계약 체결에 필요한 서류(사업자등록증·대표자 신분증·통장 사본 등)를 회사에 제출하여야 하며, 보완 요구에도 성실히 응하여야 한다. | D20: ② 계약자는 사용자(라이더)가 운행되는 전 기간에 대하여 위치정보 수집·이용·제공의 적법성을 확보할 책임을 부담하며, 이와 관련하여 제3자로부터 회사에 제기되는 일체의 청구·손해·과태료에 대하여 계약자가 전적으로 책임진다.
B21: ② 제출된 서류는 어떠한 경우에도 반환하지 아니한다. | D21: ③ 계약자는 위치정보 장치를 임의로 변경·제거·훼손할 수 없다.
D22: ④ 회사는 채무불이행, 계약 해지, 회수 절차, 보험사고 처리 등 본 계약 이행·관리에 필요한 범위 내에서만 위치정보를 활용한다.
B23: 제4조 (이륜차의 인도 및 확인)
B24: ① 회사는 계약자와 합의한 날에 지정 장소에 이륜차를 인도하며, 인도일부터 계약이 개시된다. | D24: 제18조 (이륜차 유지비용 및 제세공과금)
B25: ② 인도 이후에는 계약자는 이륜차의 하자·결함을 이유로 렌탈료 지급의무를 거부할 수 없다. | D25: ① 계약자는 관련 법령과 관할관청·회사의 지시를 준수한다.
D26: ② 회사는 계약기간 중 언제든 본 계약 준수 여부를 점검할 수 있으며, 계약자는 성실히 협조하여야 한다.
B27: 제5조 (보증금 및 계약금) | D27: ③ 이륜차의 등록·유지·사용·등록말소·폐차 등과 관련하여 렌탈료에 포함되지 않은 비용 및 제세공과금(과태료·범칙금·벌과금 등)은 전적으로 계약자가 부담한다.
B28: ① 계약자는 계약 체결 시 회사가 지정하는 계좌(포어스바이크 유한회사)로 보증금을 지급하여야 한다. 사전 동의를 받아 보증금 지급이 지연된 경우 회사는 최대 7일의 유예기간을 둘 수 있다.
B29: ② 전항의 유예기간 내 지급이 이루어지지 않을 경우 본 계약은 자동 해지되며, 계약자는 즉시 이륜차를 반환함과 동시에 (1) 인도일부터 반환일까지의 일할 사용료, (2) 이륜차의 감가손실액, (3) 차량 등록비·번호판 비용·보험료 등 회사가 이미 지출한 부대비용 일체를 회사에 배상한다. | D29: 제19조 (금지행위)
B30: ③ 보증금은 계약기간 만료 및 계약자의 모든 채무 이행 완료 시 반환한다. 다만, 미납 과태료·수리비·구상금 등이 확인될 수 있으므로 만료일로부터 1개월 경과 후 반환한다. | D30: 계약자는 다음 행위를 하여서는 아니된다: (1) 이륜차의 무단 양도·전대 또는 본 계약상 권리를 제3자에게 양도하는 행위, (2) 보험에서 인정하는 사용자 이외의 자에게 운행하게 하는 행위, (3) 보험연령 미달자에게 운행하게 하는 행위, (4) 이륜차 규격·성능·기능을 임의로 변경하거나 번호판을 훼손하는 행위, (5) 이륜차를 제3자에게 담보 목적으로 제공하는 등 회사의 소유권 침해 행위, (6) 이륜차 부착 표지를 제거·훼손하거나 위치를 변경하는 행위, (7) 위치정보 수집 장치를 훼손·은닉하는 등 본래의 효용을 해하는 행위.
B31: ④ 미납 과태료·범칙금은 보증금에서 공제하고 잔액을 반환하며, 초과분은 계약자가 추가 납부한다.
B32: ⑤ 계약이 중도 해지된 경우 보증금 및 계약금은 반환하지 아니하며, 위약금 및 손해배상금은 별도로 청구한다. | D32: 제20조 (제3자에 대한 면책)
D33: ① 계약 기간 종료·해지 여부와 무관하게, 이륜차 인수일부터 반환일까지의 기간 동안 제3자가 회사(소유자)를 상대로 인적·물적 손해배상을 청구하는 경우 계약자는 자신의 비용·책임으로 회사를 면책시켜야 한다.
B34: 제6조 (렌탈료 및 결제) | D34: ② 회사가 소유자라는 이유로 직접 손해배상을 한 경우 계약자는 회사가 제3자에게 지급한 금액과 관련 제비용을 즉시 상환한다.
B35: ① 계약자는 공휴일과 무관하게 정해진 결제일에 회사 명의 계좌로 렌탈료 등 모든 비용을 직접 납부한다. | D35: ③ 회사가 제3자 청구에 방어를 한 경우 계약자는 방어 관련 지출된 소송비용 등 일체를 부담한다.
B36: ② 회사가 안내한 은행계좌(포어스바이크 유한회사)로 직접 입금하며, 타 계좌 입금분은 수납이 확인되지 아니할 수 있다.
B37: ③ 렌탈료는 월렌탈료 선불을 원칙으로 하며, 5일 경과 미납 시 자동으로 월렌탈료 선불로 전환된다. | D37: 제21조 (계약자에 의한 중도 해지)
B38: ④ 매도인의 가격 인상, 정부 정책, 보험사 단가 변경 등 불가피한 사정으로 렌탈료가 변동될 경우 회사는 계약자에게 개별 통지하며, 계약자는 출고 이전까지 계약을 취소할 수 있다. | D38: ① 계약자가 본 계약을 중도 해지하고자 하는 경우 해지 예정일로부터 최소 10일 전에 회사에 사전 통보한다.
B39: ⑤ 이륜차 도난·멸실·훼손 등으로 운행이 불가능한 사유가 발생하더라도 계약자는 렌탈료 지급의무를 거부할 수 없다. | D39: ② 회사의 중대한 귀책사유가 아닌 경우 계약자는 위약금을 회사에 지급한다.
B40: ⑥ 보험연령 변경 등 사유로 렌탈료가 변동될 경우 해당 차량 최초 계약 당시의 단가표 기준으로 산정한다. | D40: ③ 계약자는 해지 예정일까지 회사가 지정하는 장소에 이륜차를 반환하여야 하며, 관련 비용은 계약자가 부담한다.
D41: ④ 인수형 렌탈계약의 경우 계약 체결 이후 180일이 경과한 경우 중도해지 위약금은 면제된다.
...

Sheet 이용약관 (2)
B1: [별지] 이륜차 할부판매 계약 이용약관
B3: 제1조 (목적) | D3: ② 전항의 유예기간 내 지급이 이루어지지 않을 경우 본 계약은 자동 해지되며, 계약자는
B4: 이 약관은 포어스바이크 유한회사(이하 "회사")와 본 계약을 체결한 계약자(배달대행사) 간의 | D4: 즉시 이륜차를 반환함과 동시에 (1) 인도일부터 반환일까지의 일할 사용료, (2) 이륜차의
B5: 이륜차 종합렌트에 관한 권리·의무를 규정함을 목적으로 한다. | D5: 감가손실액, (3) 차량 등록비·번호판 비용·보험료 등 회사가 이미 지출한 부대비용 일체를
D6: 회사에 배상하여야 한다.
B7: 제2조 (용어의 정의) | D7: ③ 보증금은 계약기간 만료 및 계약자가 모든 채무를 이행한 경우 수납대행사를 통해 반환
B8: ① "이륜차 렌트 계약"이란, 회사가 계약자의 요청에 따라 이륜차를 취득하여 일정 기간 사용 | D8: 한다. 다만, 미납 과태료·수리비 등이 확인될 수 있으므로 계약기간 만료일로부터 1개월이
B9: 하게 하고 그 대가를 정기적으로 지급받는 계약을 말한다.
B10: ② "이륜차"란, 회사가 본 계약서에 특정한 이륜차로서 인도 시 부착된 부속품 및 장착물을 포 | D10: 경과한 이후에 반환한다.
B11: 함한다. | D11: ④ 반환된 이륜차 상태에 따라 보증금에서 수리비를 공제하며, 수리비가 보증금을 초과하면
B12: ③ "계약기간"이란, 계약자가 본 계약에 따라 이륜차를 인도받아 사용하는 기간을 말한다. | D12: 계약자는 차액을 추가 납부하여야 한다.
B13: ④ "보증금"이란, 렌탈료 등 본 계약상 채무이행을 담보하기 위해 계약자가 회사에 납부하는 | D13: ⑤ 미납 과태료·범칙금은 보증금에서 공제하고 잔액을 반환하며, 초과분은 계약자가 추가
B14: 금원을 말하며, 계약기간 만료 및 모든 채무 이행 완료 시 반환한다. | D14: 납부하여야 한다.
B15: ⑤ "계약자"는 본 계약 제1면에 "계약자"로 기재된 사업장(법인 또는 개인사업자)을 말하며, 본 | D15: ⑥ 계약이 중도 해지된 경우 계약자는 어떠한 사유로도 납부한 보증금 및 계약금을 반환
B16: 계약상 모든 채무를 부담한다. | D16: 받을 수 없다.
B17: ⑥ "연대보증인"은 본 계약 제1면에 기재된 계약자(사업장)의 대표자 개인을 말하며, 계약자와
B18: 연대하여 본 계약상 모든 채무를 부담한다. | D18: 제8조 (할부금 및 기타 지급금)
B19: ⑦ "사용자"는 계약자가 지정·관리하는 자로서 실제로 이륜차를 운행하는 자를 말한다. 계약자 | D19: ① 계약자는 계약서에 기재된 할부금 및 운행 관련 제 비용을 공휴일과 무관하게 정해진
B20: 는 사용자의 신원·자격·연령 관리에 대한 모든 책임을 부담하며, 회사는 사용자의 신원·연령을 | D20: 결제일에 수납대행사 계좌로 납부하여야 한다.
B21: 사전에 확인할 의무가 없다. | D21: ② 결제방법이란, 회사가 안내한 수납대행사 은행계좌로 한국은행 발행 통화를 지급하거나
B22: ⑧ "보험연령"이란, 본 계약 차량에 가입된 보험에서 운전자로서 보장 가능한 최저연령을 말하
B23: 며, 본 계약 제1면에 기재된 만 나이를 의미한다. | D23: 결제 수단을 통해 납부하는 것을 의미한다.
B24: ⑨ "위약금"이란, 계약자의 귀책사유로 주문 취소 또는 중도 해지 시 회사에 지급하여야 하는 | D24: ③ 매도인의 가격 인상, 정부 정책 등 불가피한 사정으로 할부금이 변동될 경우 회사는 계약
B25: 금액을 말한다. | D25: 자에게 개별 통지하며, 계약자는 이륜차 출고 이전까지 계약을 취소할 수 있다.
B26: ⑩ "지연손해금"이란, 계약자가 렌탈료·위약금·과태료 등의 납부를 지체한 경우 발생하는 추 | D26: ④ 이륜차의 도난·멸실·훼손으로 운행이 불가능한 사유가 발생하더라도 계약자는 할부금
B27: 가 비용을 말한다.
B28: ⑪ "구상금"이란, 본 계약 차량 운행 중 발생한 사고로 보험사가 회사에게 청구한 금액 일체를
B29: 말한다.
D30: 지급의무를 거부할 수 없다.
B31: 제3조 (서류 제출 및 보완) | D31: ⑤ 납부주기 변경으로 할부금이 조정되는 경우 최초 계약 당시의 단가표 기준에 따라
B32: ① 계약자는 본 계약 체결에 필요한 서류(사업자등록증·대표자 신분증·통장 사본 등)를 회사에 제 | D32: 산정·적용한다.
B33: 출하여야 하며, 보완 요구에도 성실히 응하여야 한다. | D33: ⑥ 회사는 연체된 할부금·위약금 등 본 계약상 채권의 회수 및 추심 업무를 수납대행사(포어
B34: ② 제출된 서류는 어떠한 경우에도 반환하지 아니한다. | D34: 스바이크 유한회사)에 위임하며, 수납대행사는 회사를 대리하여 계약자에게 독촉·추심
D35: 할 수 있다.
B36: 제4조 (소유권 유보)
B37: ① 본 계약에 따른 이륜차의 소유권은 계약자가 모든 채무를 전액 이행할 때까지 회사에 | D37: 제9조 (지연손해금 및 반환지연금)
B38: 유보된다. | D38: ① 계약자가 약정 금액을 기한 내에 이행하지 않는 경우 위약금이 발생하며, 계약자는 회사
B39: ② 계약자가 계약기간 동안 할부금을 성실히 납부하고 본 계약상 모든 채무를 완전히 이행 | D39: 의 청구일로부터 5일 이내에 지급하여야 한다.
B40: 한 경우, 회사는 지체 없이 이륜차의 소유권을 계약자에게 이전한다. | D40: ② 지연손해금 계산식: 지연손해금 = 연체금액 × 경과일수 × 연 20%
D41: ③ 반환지연금은 계약 만료·해지에도 불구하고 계약자가 이륜차를 반환하지 않고 점유·사용
...
