Workbook

Sheet 계약리스트
A1: 계약번호 | B1: 출고일자 | C1: 차종 | D1: 차대번호 | E1: 차량번호 | F1: 색상 | G1: 정비여부 | H1: 보험연령 | I1: 일사용료 | J1: 사용일수 | K1: 보증금 | L1: 계약자명 | M1: 주민번호 | N1: 주소 | O1: 연락처 | P1: 계약유형 | Q1: 상품유형 | S1: 요금결제일
A2: 1 | B2: 2026-04-24 | C2: UHR150 | D2: LWMTDKH95THJ00467 | E2: 1나88370 | F2: 화이트 | G2: 비포함 | H2: 만30세 | I2: 26400 | J2: 365 | K2: 300000 | L2: 안종식 | M2: 820530-1046518 | N2: 경기도 오산시 궐동로 77, 1층(궐동) | O2: 010-5813-7336 | P2: 렌트 | Q2: 인수형 | R2: 계좌이체 | S2: 월2회(15일,말일)

Sheet 계약서
L1: 계약번호입력→
B2: 이륜차 책임렌트 계약서 | L2: 1
B3: 한국모터사이클리스 유한회사 | F3: 계약번호 | I3: =IFERROR(TEXT($L$2,"0000"),"") -> 0001
B5: ■ 차량 정보
B6: 차종 | C6: =IFERROR(IF(VLOOKUP($L$2,계약리스트!$A$2:$AD$10000,3,0)="","",VLOOKUP($L$2,계약리스트!$A$2:$AD$10000,3,0)),"") -> UHR150 | E6: 차량번호 | F6: =IFERROR(IF(VLOOKUP($L$2,계약리스트!$A$2:$AD$10000,5,0)="","",VLOOKUP($L$2,계약리스트!$A$2:$AD$10000,5,0)),"") -> 1나88370 | H6: 색상 | I6: =IFERROR(IF(VLOOKUP($L$2,계약리스트!$A$2:$AD$10000,6,0)="","",VLOOKUP($L$2,계약리스트!$A$2:$AD$10000,6,0)),"") -> 화이트
B7: 차대번호 | C7: =IFERROR(IF(VLOOKUP($L$2,계약리스트!$A$2:$AD$10000,4,0)="","",VLOOKUP($L$2,계약리스트!$A$2:$AD$10000,4,0)),"") -> LWMTDKH95THJ00467 | E7: 정비여부 | F7: =IFERROR(IF(VLOOKUP($L$2,계약리스트!$A$2:$AD$10000,7,0)="","",VLOOKUP($L$2,계약리스트!$A$2:$AD$10000,7,0)),"") -> 비포함 | H7: 계약일자 | I7: =IFERROR(IF(VLOOKUP($L$2,계약리스트!$A$2:$AD$10000,2,0)="","",VLOOKUP($L$2,계약리스트!$A$2:$AD$10000,2,0)),"") -> 2026-04-24
B8: 보험연령 | C8: =IFERROR(IF(VLOOKUP($L$2,계약리스트!$A$2:$AD$10000,8,0)="","",VLOOKUP($L$2,계약리스트!$A$2:$AD$10000,8,0)),"") -> 만30세 | E8: ※ 본 차량은 위 보험연령 이상의 운전자만 운행 가능. 미달자 운전 사고 시 발생하는 모든 손해·구상금은 계약자가 전적으로 책임집니다.
B10: ■ 계약자
B11: 성명 | C11: =_xlfn.XLOOKUP(L2,계약리스트!A:A,계약리스트!L:L) -> 안종식 | E11: 주민등록번호 | F11: =_xlfn.XLOOKUP(L2,계약리스트!A:A,계약리스트!M:M) -> 820530-1046518 | H11: 연락처 | I11: =_xlfn.XLOOKUP(L2,계약리스트!A:A,계약리스트!O:O) -> 010-5813-7336
B12: 주소 | C12: =_xlfn.XLOOKUP(L2,계약리스트!A:A,계약리스트!N:N) -> 경기도 오산시 궐동로 77, 1층(궐동)
B13: ※ 제출 서류 : 신분증 사본
B16: ■ 계약 조건
B17: 계약유형 | C17: =_xlfn.XLOOKUP(L2,계약리스트!A:A,계약리스트!P:P) -> 렌트 | E17: 상품유형 | F17: =_xlfn.XLOOKUP(L2,계약리스트!A:A,계약리스트!Q:Q) -> 인수형 | H17: 렌트 기간 | I17: =_xlfn.XLOOKUP(L2,계약리스트!A:A,계약리스트!J:J) -> 365
B18: 일사용료 (VAT포함) | C18: =_xlfn.XLOOKUP(L2,계약리스트!A:A,계약리스트!I:I) -> 26400 | E18: 보증금 | F18: =_xlfn.XLOOKUP(L2,계약리스트!A:A,계약리스트!K:K) -> 300000 | H18: 요금결제일 | I18: =_xlfn.XLOOKUP(L2,계약리스트!A:A,계약리스트!S:S) -> 월2회(15일,말일)
B19: 납입방법 | C19: 계좌이체 | E19: 청구시작일 | F19: =TEXT(_xlfn.XLOOKUP(L2,계약리스트!A:A,계약리스트!B:B),"yyyy년 mm월 dd일") -> 2026년 04월 24일
B20: 납입계좌 | C20: 기업은행 929-028075-04-011 포어스바이크(유)
B22: ■ 회사 정보
B23: 상호 | C23: 한국모터사이클리스 유한회사 | E23: 사업자번호 | F23: 647-86-03800 | H23: 대표이사 | I23: 김현수
B24: 주소 | C24: 경기도 수원시 권선구 입북로59번길 15 | G24: 고객센터 | H24: 010-2730-7845
B26: ⚠ 주요 확인사항 (서명 전 필독)
B27: 운행자성 | D27: 회사는 본 차량의 소유자이나 자동차손해배상보장법상 "운행자"가 아니며, 운행자성(운행지배·운행이익)은 전적으로 계약자에게 있습니다. 따라서 운행 중 발생하는 모든 인적·물적 손해의 운행자 책임은 계약자가 부담하며, 이로 인해 보험사가 회사에 청구하는 구상금도 계약자가 전액 부담합니다.
B28: 사고 즉시 고지 의무 | D28: 회사는 운행자가 아니므로 사고 발생 사실을 직접 인지할 수 없습니다. 사고(인적·물적 손해, 단독사고, 차량 파손, 도난, 멸실 등 일체) 발생 시 계약자는 즉시 회사에 고지하여야 하며, 미고지·지연 고지로 발생하는 모든 손해(보험 미보장분, 회사에 청구되는 구상금, 회사 추가 부담 비용 등)는 계약자가 전적으로 책임지며 회사는 본 계약을 즉시 해지하고 차량을 회수할 수 있습니다.
B29: 보험연령 미달자 운전 | D29: 본 차량은 보험연령 이상의 운전자만이 운행해야 합니다. 보험연령 미달자가 운행하여 발생한 사고·손해·보험사 구상금은 회사의 라이더 신원·연령 확인 여부와 관계없이 계약자가 전적으로 책임지며, 회사가 보험사로부터 구상금을 청구받는 경우 통보 후 7일 이내에 전액 변제하여야 합니다.
B30: 12대 중과실·면책사고 | D30: 신호위반·중앙선침범·무면허·음주운전 등 12대 중과실 또는 보험약관상 면책사항(고의·약물·범죄·운행자 범위 외 운전·도난중 운행 등)에 해당하는 사고로 회사에 보험사 구상금이 청구되는 경우, 계약자는 통보 후 7일 이내에 전액 변제하여야 합니다.
B31: 구상금 | D31: 본 약관상 "구상금"이란 본 계약 차량 운행 중 발생한 사고로 보험사 또는 제3자가 회사에 청구하는 금액 일체를 말합니다. 운행자성·사고 미고지·보험연령 미달자 운전·12대 중과실·면책사고·보험사 보장 한도 초과 손해 등 어떠한 사유로든 회사에 구상금이 청구되는 경우, 계약자는 통보일로부터 7일 이내에 구상금 전액 및 회사가 그와 관련하여 지출한 변호사비·소송비 일체를 회사에 변제하여야 합니다.
B32: 미변제 시 즉시 처리 | D32: 위 구상금 또는 본 계약상 모든 채무를 기한 내 변제하지 아니하는 경우 본 계약은 사전 통지·최고 없이 자동 해지되며, 회사는 (1) 차량을 즉시 임의 회수하고 회수에 소요된 일체의 비용(출장비·운송비·원상복구비 포함)을 계약자에게 청구하며, (2) 보증금은 어떠한 사유로도 반환하지 아니하고, (3) 위약금[보증금 + 잔여기간 총 렌트료의 20%] 및 손해배상금을 별도 청구하며, (4) 미변제 금액에 대하여 연 15%의 지연손해금을 변제일까지 가산하고, (5) 계약자의 별도 동의 없이 신용정보집중기관에 채무불이행 사실을 등록하거나 신용정보업체에 채권추심을 의뢰할 수 있으며, (6) 회사 또는 회사의 계열사(한국모터사이클리스 유한회사 포함)와 체결한 다른 이륜차 계약도 동시에 해지하고 해당 차량들도 일괄 회수할 수 있고, (7) 계약자에 대하여 민·형사상 모든 법적 조치를 취할 수 있습니다.
B33: 1. 본 계약에 따른 모든 대금(렌트료·보증금·부대비용 등)의 수납 업무는 포어스바이크(유)가 대행하며, 현금영수증은 계약자의 주민번호로 한국모터사이클리스 유한회사 명의로 발행됩니다. 타 계좌 입금 시 입금 확인이 불가합니다.
B34: 2. 계약 취소·중도 해지 시 계약자는 이륜차 및 배달통·슬라이더 등 무상 지원 비품을 회사가 지정하는 장소로 반납하여야 하며, 보증금은 반환되지 아니하고 위약금과는 별도로 회수비용(출장비·운송비·원상복구비)은 계약자가 부담합니다.
B35: 3. 보증금 지급 유예 기간 내 미지급으로 계약이 자동 해지되는 경우, 계약자는 차량 반환과 동시에 (1) 인도일부터 반환일까지의 일할 사용료, (2) 감가손실액, (3) 등록비·번호판·보험료 등 회사가 이미 지출한 부대비용을 배상합니다.
B37: ■ 개인(신용)정보 수집·이용, 금융거래정보 제공, 업무위탁 동의
B38: 수집·이용 목적 | D38: 거래관계 설정·유지, 상품 제공, 법령상 의무 이행, 분쟁 처리, 차량 분실 방지, 사고 대응, 보험사고 처리, 운전자 확인 및 보험연령 검증, 채권 관리 등 계약 이행 전반
B39: 수집 항목 | D39: 성명(실명)·주민등록번호·휴대전화번호·현주소·신분증 정보·거래카드·계좌 정보·차량 위치정보(FMS 수집 포함)
B40: 보유·이용 기간 | D40: 수집·이용 목적 달성 후 파기. 단, 전자상거래법 등 관련 법령에 따라 계약·결제 기록 5년, 채권 관리 기록 5년, 불량이용자 재가입 방지 기록 해지 후 1년 보존
B41: 금융거래정보 제공 | D41: 신용카드·자동이체 등록·해지 시까지 회사 및 결제대행사에 거래정보 제공 (금융실명법에 따라 동의)
B42: 자동이체 동의 | D42: 매월 발생하는 렌트료, 보증금, 위약금, 과태료, 범칙금, 보험사 구상금 등을 신용카드 자동승인 또는 계좌 자동이체로 출금 거래 신청
B43: 업무위탁 내역 | D43: 협력사(공급·운송·출고 정보), 수납대행사 포어스바이크(유)(대금 수납·채권관리), 배달대행사(고객정보), 차량등록소(등록 사무), 효성에프엠에스(자동이체)
B44: 상기 "개인(신용)정보 수집·이용·제공 동의", "금융거래정보 제공 동의", "업무위탁 동의"에 대하여 □ 동의안함 □ 전부 동의함
B46: ■ 계약 체결
B47: 본인은 본 이륜차 책임렌트 계약서와 이용약관의 내용을 전부 설명 듣고 확인하였으며, 본 계약에 따른 권리·의무와 운행자성·보험연령·사고 고지·면책사고 책임 등 제반 사항에 이의 없이 동의합니다.
B48: 계약자 | C48: =_xlfn.XLOOKUP(L2,계약리스트!A:A,계약리스트!L:L) -> 안종식 | F48: (인) | G48: 공급자 | H48: 한국모터사이클리스 유한회사 | J48: (인)
...

Sheet 이용약관
B1: 이륜차 책임렌트 계약 이용약관
B3: 제1조 (목적) | D3: 제7조 (지연손해금 및 손해배상금)
B4: 이 약관은 한국모터사이클리스 유한회사(이하 "회사")와 본 계약을 체결한 계약자간의 이륜차 책임 | D4: ① 계약자가 약정 금액을 기한 내 이행하지 않는 경우 위약금이 발생하며, 회사 청구일로부터 5일 이내
B5: 렌트에 관한 권리·의무를 규정함을 목적으로 한다. | D5: 에 지급한다.
D6: ② 지연손해금: [지연손해금 = 연체금액 × 경과일수 × 연 15%].
B7: 제2조 (용어의 정의) | D7: 계약 만료 후 처리절차 지체 손해배상금: [손해배상금 = 1만원 × 지체일수].
B8: ① "이륜차 렌트 계약"이란, 회사가 계약자의 요청에 따라 이륜차를 취득하여 일정 기간 사용하게 하 | D8: ③ 지연손해금·손해배상금은 회사의 손해배상청구와 별도로 부과될 수 있다. 본 계약상 모든 미납금
B9: 고 그 대가를 정기적으로 지급받는 계약을 말한다. | D9: (렌트료·과태료·범칙금·구상금·취·등록세·수리비·위약금·손해배상금 등)에 대하여 연체·미납이 발생하
B10: ② "이륜차"란, 회사가 본 계약서에 특정한 이륜차로서 인도 시 부착된 부속품·장착물을 포함한다. | D10: 는 경우, 회사는 계약자의 별도 동의 없이 (1) 신용정보집중기관에 채무불이행 사실을 등록하거나,
B11: ③ "계약기간"이란, 계약자가 본 계약에 따라 이륜차를 인도받아 사용하는 기간을 말한다. | D11: (2) 신용정보업체 등 채권추심 전문기관에 채권추심을 위임할 수 있다. 수납대행사인 포어스바이크
B12: ④ "보증금"이란, 렌트료 등 본 계약상 채무이행을 담보하기 위해 계약자가 회사에 납부하는 금원을 | D12: 유한회사는 회사를 대리하여 계약자에게 미납금 납부 독촉을 할 수 있다.
B13: 말하며, 계약기간 만료 및 모든 채무 이행 완료 시 반환한다.
B14: ⑤ "계약자"는 본 계약 1면에 "계약자"로 기재된 라이더 본인을 말하며, 본 계약상 주채무자이자 본 | D14: 제8조 (보험계약의 체결 및 관리)
B15: 계약 차량을 실제 운행하는 자이다. | D15: ① 회사는 이륜차에 계약자가 요청하는 보험연령에 따라 책임보험(대인배상Ⅰ·대물배상)에 가입하
B16: ⑥ "계약이관"이란, 계약자가 본 계약상의 권리와 의무를 제3자에게 승계하는 것을 말한다. | D16: 며, 종합보험은 가입하지 아니한다. 본 책임보험의 보장 한도는 보험사 약관 및 보험증권에 따르며,
B17: ⑦ "보험연령"이란, 본 계약 차량에 가입된 보험에서 운전자로서 보장 가능한 최저연령을 말하며, 본 | D17: 보장 한도를 초과하는 손해(대물 손해 한도 초과분·대인 한도 초과분 등)는 전적으로 계약자가 부담
B18: 계약 1면에 기재된 만 나이를 의미한다. | D18: 한다. 보험료는 회사가 납부한다.
B19: ⑧ "위약금"이란, 계약자의 귀책사유로 주문 취소 또는 중도 해지 시 회사에 지급하여야 하는 금액을 | D19: ② 보험사 정책상 보험연령 변경이 불가능한 경우 회사는 계약자에게 즉시 통지한다.
B20: 말한다. | D20: ③ 보험연령 변경에 따라 렌트료가 변경될 경우 해당 차량 최초 계약 당시 단가표 기준으로 적용된다.
B21: ⑨ "지연손해금"이란, 계약자가 렌트료·위약금·과태료 등의 납부를 지체한 경우 발생하는 추가 비용을 | D21: 보험사 정책상 고가의 보험료를 수취하는 경우 보험사 보험료 정책에 따라 고가의 렌트료가 적용될
B22: 말한다. | D22: 수 있다.
B23: ⑩ "구상금"이란, 본 계약 차량 운행 중 발생한 사고로 보험사가 회사에게 청구한 금액 일체를 말한다. | D23: ④ 계약 해지 사유 발생 시 회사는 보험을 해지할 수 있으며, 이로 인해 발생하는 보험환급금은 회사
B24: ⑪ "책임보험"이란, 자동차손해배상보장법에 따른 의무보험으로서 대인배상Ⅰ과 대물배상을 보장하 | D24: 에 귀속되고 계약자는 이에 대한 추가 환급을 청구할 수 없다.
B25: 는 보험을 말한다. | D25: ⑤ 회사는 계약기간과 일치하게 보험계약을 체결한다. 계약 종료일 이후 무보험 상태에서 운행하여
B26: ⑫ "종합보험"이란, 책임보험에 대인배상Ⅱ를 추가로 담보하는 보험을 말한다. | D26: 손해가 발생하면 계약자가 배상책임 및 민·형사상 책임을 진다.
B27: ⑬ "미수선처리"란, 사고 발생 시 계약자가 차량을 수리하지 아니하고 임의로 수리비 전부 또는 일부 금
B28: 액을 현금으로 지급받는 행위를 말한다. | D28: 제9조 (운행자성 및 운행지배)
B29: ⑭ "플랫폼 일차감 프로그램"이란, 계약자가 가맹중인 배달플랫폼 본사와 회사 간의 제휴계약이 체결 | D29: ① 본 계약 차량의 소유권은 회사에 있으나, 회사는 자동차손해배상보장법 제3조에서 정한 "자기를
B30: 되어 있는 경우 해당 플랫폼사의 페이를 통해 렌트료·과태료 등 납부가 가능한 전산 시스템을 말한다. | D30: 위하여 자동차를 운행하는 자"(이하 "운행자")에 해당하지 아니한다. 회사는 본 계약 차량에 대한 운
D31: 행지배 및 운행이익을 갖지 아니한다.
B32: 제3조 (서류 제출 및 이륜차 인도) | D32: ② 본 계약 차량의 운행자는 계약자이며, 운행 중 발생하는 모든 인적·물적 손해에 대한 운행자 책임
B33: ① 계약자는 본 계약 체결에 필요한 서류를 회사에 제출하여야 하며, 보완 요구에도 성실히 응한다. | D33: 은 전적으로 계약자가 부담한다. 계약자가 제3자에게 차량을 운행하게 한 경우에도 운행자성은 여
B34: 제출된 서류는 어떠한 경우에도 반환하지 아니한다. | D34: 전히 계약자에게 있다.
B35: ② 회사는 청구시작일부터 지정 장소에 이륜차를 인도하며, 해당 날짜부터 계약이 개시된다. | D35: ③ 제3자가 회사를 상대로 운행자 책임을 청구하는 경우 계약자는 자신의 비용·책임으로 회사를 면책
B36: 인도 이후에는 계약자는 이륜차의 하자·결함을 이유로 렌트료 지급의무를 거부할 수 없다. | D36: 시켜야 하며, 회사가 부득이 배상한 경우 그 금액 및 관련 비용 일체를 즉시 회사에 상환하여야 한다.
B38: 제4조 (소유권 유보 및 이전) | D38: 제10조 (사고 발생 시 고지 의무)
B39: ① 본 계약에 따른 이륜차의 소유권은 계약자가 모든 채무를 전액 이행할 때까지 회사에 유보된다. | D39: ① 회사는 본 계약 차량의 운행자가 아니므로 사고 발생 사실을 직접 인지할 수 없다. 따라서 본 조의
B40: ② 인수형 계약의 경우, 계약자가 모든 채무를 완전히 이행한 때 회사는 회사의 내부 행정 절차에 따라 | D40: 고지 의무는 본 계약상 계약자의 핵심 의무에 해당한다.
B41: 이륜차의 소유권을 계약자에게 이전한다. | D41: ② 다음 사유 발생 시 계약자는 즉시 회사에 고지하여야 한다: 인적·물적 손해사고, 단독사고·차량 파
B42: ③ 반납형 계약의 경우 이륜차의 소유권은 계약 종료 후에도 회사에 귀속된다. | D42: 손, 도난·멸실·분실, 보험사 접수 필요 사건, 무면허·음주·약물·범죄 목적 운전 등 면책사유 해당 운행
...

Sheet 별지_구상금
B2: 구상금 관련 특약 확인서
B3: 본 별지는 이륜차 책임렌트 계약에 부속되며 본 계약서 본문과 동일한 효력을 가집니다.
B5: 본인은 본 계약과 관련하여 발생할 수 있는 "구상금"의 책임 범위, 변제 기한, 미변제 시 회사의 조치 사항에 대하여 별도로 충분히 설명듣고 이해하였으며, 아래 내용 전부에 동의합니다.
B7: 제1조 구상금의 정의
B8: "구상금"이란 본 계약 차량의 운행 중 발생한 사고로 보험사 또는 제3자가 회사에 청구하는 금액 일체를 말하며, 원금·지연이자·소송비용·변호사비 등 회사가 그와 관련하여 지출한 모든 비용을 포함한다.
B10: 제2조 구상금이 발생하는 주요 사유
B11: 다음 각 호에 해당하는 사고로 회사가 구상금을 청구받는 경우 그 책임은 전적으로 계약자에게 있다.
B12: ① | C12: 운행자성 | D12: 회사는 차량 소유자이나 자동차손해배상보장법상 운행자가 아니다. 운행자성은 전적으로 계약자에게 있으며, 보험사가 회사에 청구하는 구상금은 계약자가 전액 부담한다.
B13: ② | C13: 사고 미고지 위반 | D13: 사고 발생 시 즉시 회사에 고지하지 아니하거나 지연·허위 고지로 발생하는 미보장 손해와 회사에 청구되는 구상금 일체를 계약자가 부담한다.
B14: ③ | C14: 보험연령 미달자 운전 | D14: 보험연령 미달자가 본 차량을 운행하여 발생한 사고·손해·구상금은 회사의 신원·연령 확인 여부와 관계없이 계약자가 책임진다.
B15: ④ | C15: 12대 중과실·면책사고 | D15: 신호위반·중앙선침범 등 12대 중과실 또는 보험약관상 면책사항에 해당하는 사고로 발생한 구상금은 계약자가 전액 부담한다.
B16: ⑤ | C16: 무면허·음주·약물 운전 | D16: 무면허·음주·약물 영향 하의 운전 및 운전자 자격 미충족자의 운행으로 발생한 사고·구상금은 계약자가 전적으로 책임진다.
B17: ⑥ | C17: 보험 보장 한도 초과 | D17: 대물배상 한도 초과분·대인배상Ⅱ 한도 초과분 등 보험사 보장 한도를 초과하는 손해는 계약자가 전액 부담한다.
B18: ⑦ | C18: 기타 보험약관상 면책사유 | D18: 운전자 범위 위반·사고 후 도주·고의 사고·유상운송 부적합 보험·차량 무단 양도·전대·무보험 운행 등 보험약관상 면책사유에 해당하는 일체의 손해를 계약자가 전적으로 책임진다.
B19: 제3조 구상금의 변제 기한
B20: 회사가 보험사 또는 제3자로부터 구상금을 청구받았다는 사실을 계약자에게 통보한 날로부터 7일 이내에, 계약자는 구상금 전액 및 회사가 지출한 변호사비·소송비 일체를 회사에 변제하여야 한다.
B22: 제4조 미변제 시 즉시 처리
B23: 제3조의 변제 기한 내에 계약자가 구상금을 변제하지 아니하는 경우 본 계약은 사전 통지·최고 없이 자동 해지되며, 회사는 다음 각 호의 조치를 동시에 또는 순차적으로 취할 수 있다.
B24: ① | C24: 차량 즉시 회수 | D24: 회수에 소요된 일체의 비용(출장비·운송비·원상복구비 포함)은 계약자가 부담한다.
B25: ② | C25: 보증금 전액 미반환 | D25: 어떠한 사유로도 보증금은 반환되지 아니한다.
B26: ③ | C26: 위약금·손해배상금 청구 | D26: 위약금 = 보증금 + (잔여기간 총 렌트료 × 20%) 산식에 따라 부과하며, 손해배상금도 별도 청구한다.
B27: ④ | C27: 연 15% 지연손해금 | D27: 미변제 금액에 대하여 연 15%의 지연손해금을 변제일까지 가산한다.
B28: ⑤ | C28: 신용정보 등록·채권추심 | D28: 별도 동의 없이 신용정보집중기관에 채무불이행 사실을 등록하거나 채권추심을 의뢰할 수 있다.
B29: ⑥ | C29: 민·형사상 법적 조치 | D29: 계약자에 대하여 민·형사상 모든 법적 조치를 취할 수 있다.
B32: 본인은 위 특약 내용(제1조 ~ 제4조) 전부를 충분히 설명듣고 이해하였으며, 본 특약에 동의함을 확인합니다.
B34: 계약자 | C34: =[1]계약서!c11 -> #NAME? | I34: (인)
B36: 공급자 | C36: 한국모터사이클리스 유한회사 | I36: (인)
