Workbook

Sheet 계약리스트
A1: 계약번호 | B1: 출고일자 | C1: 차종 | D1: 차대번호 | E1: 차량번호 | F1: 색상 | G1: 정비여부 | I1: 일사용료 | J1: 사용일수 | K1: 보증금 | L1: 사업장 업체명 | M1: 사업자번호 | N1: 대표자명 | O1: 업체주소 | P1: 사업장 연락처 | Q1: 사업장 이메일 | R1: 대표자 주민번호 | S1: 대표자 연락처 | T1: 대표자 주소 | U1: 계약유형 | V1: 상품유형 | W1: 납입방법 | X1: 납입계좌 | Y1: 요금결제일 | Z1: 사업자유형 | AA1: 법인등록번호 | AB1: 계산서 발행 주기
A2: 1 | B2: 2026-04-24 | C2: UHR150 | D2: LWMTDKH95THJ00467 | E2: 1나88370 | F2: 화이트 | G2: 비포함 | I2: 26400 | J2: 365 | K2: 300000 | L2: 중앙 오토바이 가수점 | M2: 737-55-00719 | N2: 안종식 | O2: 경기도 오산시 가장로 763, 1층 5,6호(가수동) | P2: 010-5813-7336 | Q2: jungang@example.com | R2: 820530-1046518 | S2: 010-5813-7336 | T2: 경기도 오산시 궐동로 77, 1층(궐동) | U2: 할부판매 | V2: 인수형 | W2: 계좌이체 | X2: 기업은행 929-028075-04-011 포어스바이크(유) | Y2: 월2회(15일,말일) | Z2: 개인사업자 | AB2: =IF(Y2="월2회(15일,말일)","월2회 (15일·말일)",IF(Y2="","","월1회 (말일)")) -> 월2회 (15일·말일)

Sheet 계약서
L1: 계약번호입력→
B2: 이륜차 할부판매 계약서 | L2: 1
B3: 한국모터사이클리스 유한회사
B5: ■ 차량 정보
B6: 차종 | C6: =IFERROR(IF(VLOOKUP($L$2,계약리스트!$A$2:$AD$10000,3,0)="","",VLOOKUP($L$2,계약리스트!$A$2:$AD$10000,3,0)),"") -> UHR150 | E6: 차량번호 | F6: =IFERROR(IF(VLOOKUP($L$2,계약리스트!$A$2:$AD$10000,5,0)="","",VLOOKUP($L$2,계약리스트!$A$2:$AD$10000,5,0)),"") -> 1나88370 | H6: 색상 | I6: =IFERROR(IF(VLOOKUP($L$2,계약리스트!$A$2:$AD$10000,6,0)="","",VLOOKUP($L$2,계약리스트!$A$2:$AD$10000,6,0)),"") -> 화이트
B7: 차대번호 | C7: =IFERROR(IF(VLOOKUP($L$2,계약리스트!$A$2:$AD$10000,4,0)="","",VLOOKUP($L$2,계약리스트!$A$2:$AD$10000,4,0)),"") -> LWMTDKH95THJ00467 | E7: 정비여부 | F7: =IFERROR(IF(VLOOKUP($L$2,계약리스트!$A$2:$AD$10000,7,0)="","",VLOOKUP($L$2,계약리스트!$A$2:$AD$10000,7,0)),"") -> 비포함 | H7: 계약일자 | I7: =IFERROR(IF(VLOOKUP($L$2,계약리스트!$A$2:$AD$10000,2,0)="","",VLOOKUP($L$2,계약리스트!$A$2:$AD$10000,2,0)),"") -> 2026-04-24
B8: ※ 본 계약은 계약자가 본인 명의로 직접 보험에 가입하는 상품이며, 회사는 출고 당시 외에는 보험 가입 여부를 확인할 수 없으므로, 운전 사고 시 발생하는 모든 손해·구상금은 계약자가 전적으로 책임집니다.
B10: ■ 계약자
B11: 업체명 | C11: =IFERROR(IF(VLOOKUP($L$2,계약리스트!$A$2:$AD$10000,12,0)="","",VLOOKUP($L$2,계약리스트!$A$2:$AD$10000,12,0)),"") -> 중앙 오토바이 가수점 | E11: 사업자번호 | F11: =IFERROR(IF(VLOOKUP($L$2,계약리스트!$A$2:$AD$10000,13,0)="","",VLOOKUP($L$2,계약리스트!$A$2:$AD$10000,13,0)),"") -> 737-55-00719 | H11: 대표자명 | I11: =IFERROR(IF(VLOOKUP($L$2,계약리스트!$A$2:$AD$10000,14,0)="","",VLOOKUP($L$2,계약리스트!$A$2:$AD$10000,14,0)),"") -> 안종식
B12: 연락처 | C12: =IFERROR(IF(VLOOKUP($L$2,계약리스트!$A$2:$AD$10000,16,0)="","",VLOOKUP($L$2,계약리스트!$A$2:$AD$10000,16,0)),"") -> 010-5813-7336 | E12: 업체주소 | F12: =IFERROR(IF(VLOOKUP($L$2,계약리스트!$A$2:$AD$10000,15,0)="","",VLOOKUP($L$2,계약리스트!$A$2:$AD$10000,15,0)),"") -> 경기도 오산시 가장로 763, 1층 5,6호(가수동)
B13: ※ 제출서류: 사업자등록증 사본, 대표자 신분증 사본
B15: ■ 연대보증인
B16: 성명 | C16: =IFERROR(IF(VLOOKUP($L$2,계약리스트!$A$2:$AD$10000,14,0)="","",VLOOKUP($L$2,계약리스트!$A$2:$AD$10000,14,0)),"") -> 안종식 | E16: 주민등록번호 | F16: =IFERROR(IF(VLOOKUP($L$2,계약리스트!$A$2:$AD$10000,18,0)="","",VLOOKUP($L$2,계약리스트!$A$2:$AD$10000,18,0)),"") -> 820530-1046518 | H16: 연락처 | I16: =IFERROR(IF(VLOOKUP($L$2,계약리스트!$A$2:$AD$10000,19,0)="","",VLOOKUP($L$2,계약리스트!$A$2:$AD$10000,19,0)),"") -> 010-5813-7336
B17: 주소 | C17: =IFERROR(IF(VLOOKUP($L$2,계약리스트!$A$2:$AD$10000,20,0)="","",VLOOKUP($L$2,계약리스트!$A$2:$AD$10000,20,0)),"") -> 경기도 오산시 궐동로 77, 1층(궐동)
B18: ※ 법인사업자의 경우 법인대표 개인 | 제출서류: 신분증 사본 | 보증 기한: 2년 | 보증 한도: 전체 이용료의 130%
B20: ■ 계약 조건
B21: 계약유형 | C21: =IFERROR(IF(VLOOKUP($L$2,계약리스트!$A$2:$AD$10000,21,0)="","",VLOOKUP($L$2,계약리스트!$A$2:$AD$10000,21,0)),"") -> 할부판매 | E21: 상품유형 | F21: =IFERROR(IF(VLOOKUP($L$2,계약리스트!$A$2:$AD$10000,22,0)="","",VLOOKUP($L$2,계약리스트!$A$2:$AD$10000,22,0)),"") -> 인수형 | H21: 할부 기간 | I21: =IFERROR(VLOOKUP($L$2,계약리스트!$A$2:$AD$10000,10,0)&"일","") -> 365일
B22: 일납입 할부금 (VAT포함) | C22: =IFERROR(TEXT(VLOOKUP($L$2,계약리스트!$A$2:$AD$10000,9,0),"#,##0")&" 원","") -> 26,400 원 | E22: 보증금 | F22: =IFERROR(TEXT(VLOOKUP($L$2,계약리스트!$A$2:$AD$10000,11,0),"#,##0")&" 원","") -> 300,000 원 | H22: 요금결제일 | I22: =IFERROR(IF(VLOOKUP($L$2,계약리스트!$A$2:$AD$10000,25,0)="","",VLOOKUP($L$2,계약리스트!$A$2:$AD$10000,25,0)),"") -> 월2회(15일,말일)
B23: 납입방법 | C23: =IFERROR(IF(VLOOKUP($L$2,계약리스트!$A$2:$AD$10000,23,0)="","",VLOOKUP($L$2,계약리스트!$A$2:$AD$10000,23,0)),"") -> 계좌이체 | E23: 청구시작일 | F23: =TEXT(_xlfn.XLOOKUP(L2,계약리스트!A:A,계약리스트!B:B),"yyyy년 mm월 dd일") -> 2026년 04월 24일
B24: 납입계좌 | C24: 기업은행 929-028075-04-011 포어스바이크(유)
B26: ■ 회사 정보
B27: 상호 | C27: 한국모터사이클리스 유한회사 | E27: 사업자번호 | F27: 647-86-03800 | H27: 대표이사 | I27: 김현수
B28: 주소 | C28: 경기도 수원시 권선구 입북로59번길 15 | G28: 고객센터 | H28: 031-296-7845
B30: ⚠ 주요 확인사항 (서명 전 필독)
B31: 운행자성 | D31: 회사는 본 차량의 소유자이나 자동차손해배상보장법상 "운행자"가 아니며, 운행자성(운행지배·운행이익)은 전적으로 계약자에게 있습니다. 따라서 운행 중 발생하는 모든 인적·물적 손해의 운행자 책임은 계약자가 부담합니다.
B32: 사고 즉시 고지 의무 | D32: 회사는 운행자가 아니므로 사고 발생 사실을 직접 인지할 수 없습니다. 사고(인적·물적 손해, 단독사고, 차량 파손, 도난, 멸실 등 일체) 발생 시 계약자는 즉시 회사에 고지하여야 하며, 미고지·지연 고지로 발생하는 모든 손해(보험 미보장 손해, 구상금·과태료, 소송비용·변호사비, 그 밖에 미고지·지연 고지로 인하여 회사가 입은 손해 일체)는 계약자가 전적으로 책임지며 회사는 본 계약을 즉시 해지하고 차량을 회수할 수 있습니다.
B33: 사용자(라이더) 관리 책임 | D33: 계약자(배달대행사)는 본 차량을 운행하는 사용자(라이더)의 신원·면허·보험 적합성·음주여부 등 운행자격을 직접 관리할 의무가 있습니다. 회사는 사용자의 신원·자격을 사전에 확인할 의무가 없으며, 사용자가 일으킨 사고·손해·보험사 구상금은 사용자의 행위라 하더라도 관리·감독을 해태한 계약자가 전적으로 책임집니다(가입된 보험 보장범위 부적합자 운전, 무면허, 음주, 12대 중과실 등 면책사고 포함).
B34: 12대 중과실·면책사고 | D34: 신호위반·중앙선침범·무면허·음주운전 등 12대 중과실 또는 보험약관상 면책사항(고의·약물·범죄·운행자 범위 외 운전·도난중 운행 등)에 해당하는 사고로 회사에 보험사 구상금이 청구되는 경우, 계약자는 통보 후 7일 이내에 전액 변제하여야 합니다.
B35: 구상금 | D35: 본 약관상 "구상금"이란 본 계약 차량 운행 중 발생한 사고로 보험사 또는 제3자가 회사에 청구하는 금액 일체를 말합니다. 운행자성·사고 미고지·사용자(라이더) 관리 책임·보험 부적합자 운전·12대 중과실·면책사고·보험사 보장 한도 초과 손해 등 어떠한 사유로든 회사에 구상금이 청구되는 경우, 계약자는 통보일로부터 7일 이내에 구상금 전액 및 회사가 그와 관련하여 지출한 변호사비·소송비 일체를 회사에 변제하여야 합니다.
B36: 미변제 시 즉시 처리 | D36: 위 구상금 또는 본 계약상 모든 채무를 기한 내 변제하지 않는 경우 본 계약은 사전 통지·최고 없이 해지되며, 회사는 (1) 차량을 즉시 임의 회수하고 회수에 소요된 일체의 비용(출장비·운송비·원상복구비 포함)을 계약자에게 청구하며, (2) 보증금은 계약자의 귀책으로 본 계약이 해지되는 경우 반환하지 않고, (3) 위약금[잔여기간 총 할부금 × 20%] 및 손해배상금을 별도 청구하며, (4) 미변제 금액에 대하여 연 15%의 지연손해금을 변제일까지 가산하고, (5) 계약자에게 통지한 후 관련 법령이 정하는 절차에 따라 신용정보회사·신용정보집중기관에 채무불이행 사실을 등록하거나 채권추심 전문기관에 추심을 위임할 수 있으며, (6) 회사 또는 회사의 계열사(포어스바이크 유한회사 포함)와 체결한 다른 이륜차 계약도 동시에 해지하고 해당 차량들도 일괄 회수할 수 있고, (7) 계약자 및 연대보증인에 대하여 민·형사상 모든 법적 조치를 취할 수 있습니다.
B37: 계열사 미납 교차 적용 | D37: 계약자가 회사 또는 회사의 계열사(포어스바이크 유한회사 포함)와 체결한 모든 이륜차 계약은 미수금 발생 시 상호 영향을 미칩니다. 포어스바이크에서 발생한 미수금은 본 계약에, 본 계약에서 발생한 미수금은 포어스바이크 계약에 동일하게 작용하며, 미수금이 7일 이상 지속되는 경우 어느 회사든 자사 계약을 해지하고 차량을 즉시 회수할 수 있습니다. 본 조 적용을 위하여 계약자는 회사와 포어스바이크 간 미수금·계약·결제 관련 정보 공유에 동의합니다. 공유 항목은 사업자등록번호, 미수금 금액·발생일, 연대보증인 성명·연락처에 한하며, 보유기간은 미수금 변제일까지로 합니다.
B38: 보증금 처리 | D38: 계약 취소·중도 해지 시 보증금은 반환되지 않으며, 위약금 및 손해배상금은 별도로 청구됩니다.
B39: 수납 방식 및 계산서 | D39: 본 계약 모든 대금은 수납대행사 포어스바이크(유) 명의 계좌로 직접 입금되며, 타 계좌 입금 시 수납이 확인되지 않을 수 있습니다. 세금계산서는 한국모터사이클리스 유한회사 명의로 발행되며, 발행 주기는 결제 주기와 동일합니다(월1회 결제 → 월1회 발행, 월2회 결제 → 월2회 발행).
B41: ■ 개인(신용)정보 수집·이용, 금융거래정보 제공, 업무위탁 동의
B42: 수집·이용 목적 | D42: 거래관계 설정·유지, 상품 제공, 법령상 의무이행, 분쟁처리, 차량 분실 방지, 사고 대응, 보험사고 처리, 채권 관리 등 계약 이행 전반
B43: 수집 항목 | D43: 사업장 상호·사업자번호·주소·연락처·이메일, 대표자 성명·주민등록번호·휴대전화번호·주소, 거래계좌 정보, 차량 위치정보(FMS 수집 포함)
B44: 보유·이용 기간 | D44: 수집 목적 달성 후 파기. 단, 전자상거래법 등 관련 법령에 따라 계약·결제 기록 5년, 불량이용자 재가입 방지 기록 해지 후 1년 보존
B45: 금융거래정보 제공 | D45: 신용카드·자동이체 등록·해지 시까지 회사 및 결제대행사에 거래정보 제공 (금융실명법에 따라 동의)
B46: 자동이체 동의 | D46: 매월 발생하는 할부금, 보증금, 위약금, 과태료, 범칙금, 보험사 구상금 등을 신용카드 자동승인 또는 계좌 자동이체로 출금 거래 신청
B47: 업무위탁 내역
...

Sheet 이용약관
B1: 이륜차 할부판매 계약 이용약관
B3: 제1조 (목적) | D3: 제8조 (지연손해금 및 처리 지체 위약금)
B4: 이 약관은 한국모터사이클리스 유한회사(이하 "회사")와 본 계약을 체결한 계약자 간의 이륜차 할부판매에 | D4: ① 계약자가 계약상 약정된 채무를 기한 내 이행하지 않는 경우 위약금이 발생하며, 위약금 발생 시 회사
B5: 관한 권리·의무를 규정함을 목적으로 한다. | D5: 청구일로부터 7일 이내에 지급한다.
D6: ② "지연손해금"이란, 계약자가 할부금·해지위약금·수리비·과태료 등 회사에 지급할 금액의 납부를 지체한
B7: 제2조 (용어의 정의) | D7: 경우 발생하는 금원을 말하며, 다음 산식에 따라 산정한다.
B8: ① "이륜차 할부판매 계약"이란, 회사가 계약자의 요청에 따라 이륜차를 취득하여 일정 기간 사용하게 하고 | D8: [지연손해금 = 연체금액 × 경과일수 × 연 15%]
B9: 그 대가를 정기적으로 지급받는 계약을 말한다. | D9: ③ "처리 지체 위약금"이란, 할부금 완납 후 명의이전·사용폐지 등 처리절차의 지체로 회사에 발생하는
B10: ② "이륜차"란, 회사가 본 계약서에 특정한 이륜차로서 인도 시 부착된 부속품·장착물을 포함한다. | D10: 비용 및 위약을 보전하는 금원을 말하며, 다음 각 호를 합산하여 산정한다.
B11: ③ "계약기간"이란, 계약자가 본 계약에 따라 이륜차를 인도받아 사용하는 기간을 말한다. | D11: 1. 정액 처리비: [1만원 × 지체일수] (회사 행정처리·관리 비용)
B12: ④ "보증금"이란, 할부금 등 본 계약상 채무이행을 담보하기 위해 계약자가 회사에 납부하는 금원을 말하 | D12: 2. 실비: 회사가 실제 부담한 사용폐지·이전등록 신고지연 과태료, 자동차세 등 명의 유지로 부과된
B13: 며, 계약기간 만료 및 모든 채무 이행 완료 시 반환한다. | D13: 제세공과금 일체.
B14: ⑤ "계약자"는 본 계약 1면에 "계약자"로 기재된 사업장을 말하며, 본 계약상 모든 채무를 부담한다.
B15: ⑥ "연대보증인"이란, 본 계약 1면에 기재되어 계약자와 연대하여 모든 채무를 부담하는 자를 말한다. | D15: 제9조 (연대보증인의 책임)
B16: ⑦ "사용자"란, 계약자가 지정·관리하는 자로서 실제로 이륜차를 운행하는 자를 말한다. | D16: ① 연대보증인은 할부금 지급채무를 포함하여 계약자가 회사에 부담하는 일체의 채무를 보증하며, 계약
B17: ⑧ "보험 적합 운전자"란, 본 계약 차량에 가입된 보험의 보장범위(운전자 범위·연령·유상운송 적합 | D17: 자와 연대하여 그 채무를 이행한다.
B18: 여부 등)에 부합하는 자를 말한다. | D18: ② 계약자가 회사 동의 없이 본 계약상 채무를 제3자에게 인수·승계시킨 경우에도 연대보증인은 채무가
B19: ⑨ "위약금"이란, 계약자의 귀책사유로 주문 취소 또는 중도 해지 시 회사에 지급하여야 하는 금액을 말한 | D19: 전액 변제될 때까지 보증채무를 부담한다.
B20: 다. | D20: ③ 연대보증인은 계약자의 미변제 채무가 남아있는 경우 계약자의 채무를 회사보다 먼저 변제 받을 권리
B21: ⑩ "구상금"이란, 본 계약 차량 운행 중 발생한 사고로 인해 보험사가 회사에 청구한 금액 일체를 말한다. | D21: 를 행사할 수 없다.
B22: ⑪ "미수선처리"란, 사고 발생 시 계약자가 차량을 수리하지 아니하고 임의로 수리비 전부 또는 일부 금액 | D22: ④ 할부금·운전자 범위 변경 등 일부 계약 내용 변경 시 연대보증인이 별도 서명·날인하지 않더라도 동의
B23: 을 현금으로 지급받는 행위를 말한다. | D23: 한 것으로 본다. 변경 내용이 연대보증인에게 불리한 경우 계약자는 즉시 통지하여야 하며, 14일 이내 이의
B24: ⑫ "플랫폼 일차감 프로그램"이란, 계약자가 가맹중인 배달플랫폼 본사와 회사 간의 제휴계약이 체결되어 | D24: 제기 시 회사는 새 보증인의 추가·교체를 요구할 수 있다.
B25: 있는 경우 해당 플랫폼사의 페이를 통해 할부금·과태료 등 납부가 가능한 전산 시스템을 말한다. | D25: ⑤ 계약자가 법인인 경우 본 계약 1면에 기재된 법인대표가 연대보증인이 된다. 개인사업자의 경우 사업
D26: 자 본인이 채무자이므로 별도의 연대보증인을 두지 않는다.
B27: 제3조 (서류 제출 및 이륜차 인도)
B28: ① 계약자는 본 계약 체결에 필요한 서류를 회사에 제출하여야 하며, 보완 요구에도 성실히 응한다. | D28: 제10조 (보험계약의 체결 및 관리)
B29: 제출된 서류는 어떠한 경우에도 반환하지 않는다. | D29: ① 본 계약 차량의 보험은 사용자(라이더)가 본인 명의로 직접 가입하며, 회사는 보험계약의 당사자가 아
B30: ② 회사는 청구시작일부터 회사가 지정한 장소에 이륜차를 인도하며, 해당 날짜부터 계약이 개시된다. 인 | D30: 니다. 회사는 보험료를 부담하지 않는다.
B31: 도 이후에는 계약자는 이륜차의 하자·결함을 이유로 할부금 지급의무를 거부할 수 없다. | D31: ② 본 차량이 유상운송 목적으로 사용되는 점을 고려하여 사용자는 유상운송 용도에 적합한 자동차보험에
B32: ③ 출고 당일 단순 변심에 의한 취소 시, 계약자는 차량 회수 비용 일체 및 위약금 10만 원을 회사에 지급 | D32: 가입하여야 한다. 부적합 보험 가입, 보장 한도 부족, 본인 명의가 아닌 보험 가입 또는 보험사 면책 등의
B33: 한다. | D33: 사유로 보험처리가 불가하거나 보험금으로 충당되지 않는 손해(회사에 대한 구상금 청구 포함)는 전적으로
D34: 계약자가 부담한다.
B35: 제4조 (소유권 유보 및 이전) | D35: ③ 계약자는 사용자의 보험 가입 여부 및 유상운송 적합성을 사전에 확인할 의무가 있으며, 본 계약 기간
B36: ① 본 계약에 따른 이륜차의 소유권은 계약자가 모든 채무를 전액 이행할 때까지 회사에 유보된다. | D36: 중 보험 갱신·해지·내용 변경을 관리·감독한다. 계약자는 회사에 사용자의 보험가입증명서를 제출하여야
B37: ② 인수형 계약의 경우, 계약자가 모든 채무를 완전히 이행한 때 회사는 회사의 내부 행정 절차에 따라 이 | D37: 하며, 변경 시 즉시 회사에 통지한다.
B38: 륜차의 소유권을 계약자에게 이전한다. | D38: ④ 계약 종료 후 무보험 상태에서 운행하여 발생한 사고는 계약자가 전적으로 책임지며 회사는 민사상
B39: ③ 반납형 계약의 경우 이륜차의 소유권은 계약 종료 후에도 회사에 귀속된다. | D39: 책임을 지지 않는다.
B40: ④ 인수형 계약이라 하더라도 계약기간 만료 및 약정 금액의 완납 전에는 계약자는 이륜차의 소유권을 주
B41: 장할 수 없다.
...

Sheet 별지_구상금
B2: 구상금 관련 특약 확인서
B3: 본 별지는 이륜차 할부판매 계약(B2B)에 부속되며 본 계약서 본문과 동일한 효력을 가집니다.
B5: 본인(계약자 및 연대보증인)은 본 계약과 관련하여 발생할 수 있는 "구상금"의 책임 범위, 변제 기한, 미변제 시 회사의 조치 사항에 대하여 별도로 충분히 설명 듣고 이해하였으며, 아래 내용 전부에 동의합니다.
B7: 제1조 구상금의 정의
B8: "구상금"이란 본 계약 차량의 운행 중 발생한 사고로 보험사 또는 제3자가 회사에 청구하는 금액 일체를 말하며, 원금·지연이자·소송비용·변호사비 등 회사가 그와 관련하여 지출한 모든 비용을 포함한다.
B10: 제2조 구상금이 발생하는 주요 사유
B11: 다음 각 호에 해당하는 사고로 회사가 구상금을 청구받는 경우 그 책임은 전적으로 계약자에게 있다.
B12: ① | C12: 운행자성 | D12: 회사는 차량 소유자이나 자동차손해배상보장법상 운행자가 아니다. 운행자성은 전적으로 계약자(배달대행사)에게 있으며, 보험사가 회사에 청구하는 구상금은 계약자가 전액 부담한다.
B13: ② | C13: 사고 미고지 위반 | D13: 사고 발생 시 즉시 회사에 고지하지 아니하거나 지연·허위 고지로 발생하는 미보장 손해와 회사에 청구되는 구상금 일체를 계약자가 부담한다.
B14: ③ | C14: 사용자(라이더) 관리 책임 | D14: 계약자가 사용자(라이더)의 신원·면허·보험 적합성·음주여부 등 운행자격 관리를 해태하여 발생한 사고·손해·구상금은 계약자가 전적으로 책임진다.
B15: ④ | C15: 보험 부적합자 운전 | D15: 가입된 보험의 보장범위에 적합하지 않은 자가 본 차량을 운행하여 발생한 사고·손해·구상금은 회사의 신원·자격 확인 여부와 관계없이 계약자가 책임진다.
B16: ⑤ | C16: 12대 중과실·면책사고 | D16: 신호위반·중앙선침범 등 12대 중과실 또는 보험약관상 면책사항에 해당하는 사고로 발생한 구상금은 계약자가 전액 부담한다.
B17: ⑥ | C17: 무면허·음주·약물 운전 | D17: 무면허·음주·약물 영향 하의 운전 및 운전자 자격 미충족자의 운행으로 발생한 사고·구상금은 계약자가 전적으로 책임진다.
B18: ⑦ | C18: 보험 보장 한도 초과 | D18: 대물배상 한도 초과분·대인배상Ⅱ 한도 초과분 등 보험사 보장 한도를 초과하는 손해는 계약자가 전액 부담한다.
B19: ⑧ | C19: 기타 보험약관상 면책사유 | D19: 운전자 범위 위반·사고 후 도주·고의 사고·유상운송 부적합 보험·차량 무단 양도·전대·무보험 운행 등 보험약관상 면책사유에 해당하는 일체의 손해를 계약자가 전적으로 책임진다.
B21: 제3조 구상금의 변제 기한
B22: 회사가 보험사 또는 제3자로부터 구상금을 청구받았다는 사실을 계약자에게 통보한 날로부터 7일 이내에, 계약자는 구상금 전액 및 회사가 지출한 변호사비·소송비 일체를 회사에 변제하여야 한다.
B24: 제4조 미변제 시 즉시 처리
B25: 제3조의 변제 기한 내에 계약자가 구상금을 변제하지 않는 경우 본 계약은 사전 통지·최고 없이 해지되며, 회사는 다음 각 호의 조치를 동시에 또는 순차적으로 취할 수 있다.
B26: ① | C26: 차량 즉시 회수 | D26: 회수에 소요된 일체의 비용(출장비·운송비·원상복구비 포함)은 계약자가 부담한다.
B27: ② | C27: 보증금 전액 미반환 | D27: 계약자의 귀책으로 본 계약이 해지되는 경우 보증금은 반환되지 아니한다.
B28: ③ | C28: 위약금·손해배상금 청구 | D28: 위약금은 [잔여기간 총 할부금 × 20%]로 산정하며, 기납부 보증금은 이와 별도로 계약 위반에 대한 위약벌로서 회사에 귀속되어 반환하지 않는다.
B29: ④ | C29: 연 15% 지연손해금 | D29: 미변제 금액에 대하여 연 15%의 지연손해금을 변제일까지 가산한다.
B30: ⑤ | C30: 신용정보 등록·채권추심 | D30: 계약자에게 통지한 후 관련 법령이 정하는 절차에 따라 신용정보회사·신용정보집중기관에 채무불이행 사실을 등록하거나 채권추심 전문기관에 추심을 위임할 수 있다.
B31: ⑥ | C31: 계열사 계약 동시 해지 | D31: 회사 또는 계열사(포어스바이크 유한회사 포함)와 체결한 다른 이륜차 계약도 동시 해지하고 차량을 일괄 회수할 수 있다.
B32: ⑦ | C32: 민·형사상 법적 조치 | D32: 계약자 및 연대보증인에 대하여 민·형사상 모든 법적 조치를 취할 수 있다.
B35: 본인(계약자·연대보증인)은 위 특약 내용(제1조 ~ 제4조) 전부를 충분히 설명 듣고 이해하였으며, 본 특약에 동의함을 확인합니다.
B37: 계약자 | C37: =IFERROR(IF(계약서!C11="","",계약서!C11),"") -> 중앙 오토바이 가수점 | I37: (인)
B39: 연대보증인 | C39: =IFERROR(IF(계약서!C16="","",계약서!C16),"") -> 안종식 | I39: (인)
B41: 공급자 | C41: 한국모터사이클리스 유한회사 | I41: (인)
