Workbook

Sheet 계약리스트
A1: 계약번호 | B1: 계약일자 | C1: 차종 | D1: 차대번호 | E1: 차량번호 | F1: 색상 | G1: 정비여부 | H1: 보험연령 | I1: 일사용료 | J1: 사용일수 | K1: 보증금 | L1: 사업장 업체명 | M1: 사업자번호 | N1: 대표자명 | O1: 업체주소 | P1: 사업장 연락처 | Q1: 사업장 이메일 | R1: 대표자 주민번호 | S1: 대표자 연락처 | T1: 대표자 주소 | U1: 계약유형 | V1: 상품유형 | W1: 납입방법 | X1: 납입계좌 | Y1: 요금결제일 | Z1: 계약유형 | AA1: 상품유형 | AB1: 납입방법 | AC1: 납입계좌 | AD1: 요금결제일
A2: 1 | B2: 2026-04-24 | C2: UHR150 | D2: LWMTDKH95THJ00467 | E2: 1나88370 | F2: 화이트 | G2: 비포함 | H2: 만30세 | I2: 26400 | J2: 365 | K2: 300000 | L2: 중앙 오토바이 가수점 | M2: 737-55-00719 | N2: 안종식 | O2: 경기도 오산시 가장로 763, 1층 5,6호(가수동) | P2: 010-5813-7336 | Q2: jungang@example.com | R2: 820530-1046518 | S2: 010-5813-7336 | T2: 경기도 오산시 궐동로 77, 1층(궐동) | U2: 할부판매 | V2: 인수형 | W2: 계좌이체 | X2: 기업은행 929-028075-04-011 포어스바이크(유) | Y2: 월2회(15일,말일) | Z2: 할부 판매 | AA2: 인수형 | AB2: 계좌이체 | AC2: 기업은행 929-028519-04-010 | AD2: 월2회(15일, 말일)

Sheet 계약서
L1: 계약번호입력→
B2: 이륜차 할부판매 계약서 | L2: 1
B3: 한국모터사이클리스 유한회사 | F3: 계약번호 | I3: =IFERROR(TEXT($L$2,"0000"),"") -> 0001
B5: ■ 차량 정보
B6: 차종 | C6: =IFERROR(IF(VLOOKUP($L$2,[1]계약리스트!$a$2:$AD$10000,3,0)="","",VLOOKUP($L$2,[1]계약리스트!$a$2:$AD$10000,3,0)),"") | E6: 차량번호 | F6: =IFERROR(IF(VLOOKUP($L$2,[1]계약리스트!$a$2:$AD$10000,5,0)="","",VLOOKUP($L$2,[1]계약리스트!$a$2:$AD$10000,5,0)),"") | H6: 색상 | I6: =IFERROR(IF(VLOOKUP($L$2,[1]계약리스트!$a$2:$AD$10000,6,0)="","",VLOOKUP($L$2,[1]계약리스트!$a$2:$AD$10000,6,0)),"")
B7: 차대번호 | C7: =IFERROR(IF(VLOOKUP($L$2,[1]계약리스트!$a$2:$AD$10000,4,0)="","",VLOOKUP($L$2,[1]계약리스트!$a$2:$AD$10000,4,0)),"") | E7: 정비여부 | F7: =IFERROR(IF(VLOOKUP($L$2,[1]계약리스트!$a$2:$AD$10000,7,0)="","",VLOOKUP($L$2,[1]계약리스트!$a$2:$AD$10000,7,0)),"") | H7: 계약일자 | I7: =IFERROR(IF(VLOOKUP($L$2,[1]계약리스트!$a$2:$AD$10000,2,0)="","",VLOOKUP($L$2,[1]계약리스트!$a$2:$AD$10000,2,0)),"")
E8: ※ 본 차량은 위 보험연령 이상의 운전자만 운행 가능. 본 계약은 계약자가 본인 명의로 직접 보험에 가입하는 상품이며, 회사는 출고 당시 외에는 보험 가입 여부를 확인할 수 없으므로, 운전 사고 시 발생하는 모든 손해·구상금은 계약자가 전적으로 책임집니다.
B9: ■ 계약자
B10: 성명 | C10: =IFERROR(IF(VLOOKUP($L$2,[1]계약리스트!$a$2:$AD$10000,14,0)="","",VLOOKUP($L$2,[1]계약리스트!$a$2:$AD$10000,14,0)),"") | E10: 주민등록번호 | F10: =IFERROR(IF(VLOOKUP($L$2,[1]계약리스트!$a$2:$AD$10000,18,0)="","",VLOOKUP($L$2,[1]계약리스트!$a$2:$AD$10000,18,0)),"") | H10: 연락처 | I10: =IFERROR(IF(VLOOKUP($L$2,[1]계약리스트!$a$2:$AD$10000,19,0)="","",VLOOKUP($L$2,[1]계약리스트!$a$2:$AD$10000,19,0)),"")
B11: 연락처 | C11: =IFERROR(IF(VLOOKUP($L$2,[1]계약리스트!$a$2:$AD$10000,16,0)="","",VLOOKUP($L$2,[1]계약리스트!$a$2:$AD$10000,16,0)),"") | E11: 업체주소 | F11: =IFERROR(IF(VLOOKUP($L$2,[1]계약리스트!$a$2:$AD$10000,15,0)="","",VLOOKUP($L$2,[1]계약리스트!$a$2:$AD$10000,15,0)),"")
B12: ※ 제출 서류 : 사업자등록증 사본, 대표자 신분증 사본
B14: ■ 연대보증인
B15: 업체명 | C15: =IFERROR(IF(VLOOKUP($L$2,[1]계약리스트!$a$2:$AD$10000,12,0)="","",VLOOKUP($L$2,[1]계약리스트!$a$2:$AD$10000,12,0)),"") | E15: 사업자번호 | F15: =IFERROR(IF(VLOOKUP($L$2,[1]계약리스트!$a$2:$AD$10000,13,0)="","",VLOOKUP($L$2,[1]계약리스트!$a$2:$AD$10000,13,0)),"") | H15: 대표자명 | I15: =IFERROR(IF(VLOOKUP($L$2,[1]계약리스트!$a$2:$AD$10000,14,0)="","",VLOOKUP($L$2,[1]계약리스트!$a$2:$AD$10000,14,0)),"")
B16: 주소 | C16: =IFERROR(IF(VLOOKUP($L$2,[1]계약리스트!$a$2:$AD$10000,20,0)="","",VLOOKUP($L$2,[1]계약리스트!$a$2:$AD$10000,20,0)),"")
B17: ※ 제출 서류 : 대표자 신분증 사본 | 보증 기한 : 2년 | 보증 한도 : 전체 이용료의 130%
B19: ■ 계약 조건
B20: 계약유형 | C20: =IFERROR(IF(VLOOKUP($L$2,계약리스트!$A$2:$AD$10000,21,0)="","",VLOOKUP($L$2,계약리스트!$A$2:$AD$10000,21,0)),"") -> 할부판매 | E20: 상품유형 | F20: =IFERROR(IF(VLOOKUP($L$2,계약리스트!$A$2:$AD$10000,27,0)="","",VLOOKUP($L$2,계약리스트!$A$2:$AD$10000,27,0)),"") -> 인수형 | H20: 할부판매기간 | I20: =IFERROR(VLOOKUP($L$2,계약리스트!$A$2:$AD$10000,10,0)&"일","") -> 365일
B21: 일사용료 (VAT포함) | C21: =IFERROR(TEXT(VLOOKUP($L$2,계약리스트!$A$2:$AD$10000,9,0),"#,##0")&" 원","") -> 26,400 원 | E21: 보증금 | F21: =IFERROR(TEXT(VLOOKUP($L$2,계약리스트!$A$2:$AD$10000,11,0),"#,##0")&" 원","") -> 300,000 원 | H21: 요금결제일 | I21: =IFERROR(IF(VLOOKUP($L$2,계약리스트!$A$2:$AD$10000,30,0)="","",VLOOKUP($L$2,계약리스트!$A$2:$AD$10000,30,0)),"") -> 월2회(15일, 말일)
B22: 납입방법 | C22: 계좌이체 | E22: 청구시작일 | F22: 차량 인도일부터
B23: 납입계좌 | C23: =IFERROR(IF(VLOOKUP($L$2,[1]계약리스트!$a$2:$AD$10000,24,0)="","",VLOOKUP($L$2,[1]계약리스트!$a$2:$AD$10000,24,0)),"")
B25: ■ 회사 정보 (공급자)
B26: 상호 | C26: 한국모터사이클리스 유한회사 | E26: 사업자번호 | F26: 647-86-03800 | H26: 대표이사 | I26: 김현수
B27: 주소 | C27: 경기도 수원시 권선구 입북로59번길 15 | G27: 고객센터 | H27: 010-2730-7845
B29: ⚠ 주요 확인사항 (서명 전 필독)
B30: 운행자성 | D30: 회사는 본 차량의 소유자이나 자동차손해배상보장법상 "운행자"가 아니며, 운행자성(운행지배·운행이익)은 전적으로 계약자에게 있습니다. 따라서 운행 중 발생하는 모든 인적·물적 손해의 운행자 책임은 계약자가 부담합니다.
B31: 사고 즉시 고지 의무 | D31: 회사는 운행자가 아니므로 사고 발생 사실을 직접 인지할 수 없습니다. 사고(인적·물적 손해, 단독사고, 차량 파손, 도난, 멸실 등 일체) 발생 시 계약자는 즉시 회사에 고지하여야 하며, 미고지·지연 고지로 발생하는 모든 손해(보험 미보장분, 회사 추가 부담 비용 등)는 계약자가 전적으로 책임지며 회사는 본 계약을 즉시 해지하고 차량을 회수할 수 있습니다.
B32: 운전자 범위 (기명 1인 한정) | D32: 본 차량의 보험은 계약자(기명 1인)를 운전자로 지정하여 가입되며, 계약자만 운행할 수 있습니다. 계약자 외의 자가 운행하여 발생한 사고·손해·보험사 구상금은 보험사 면책 가능성과 무관하게 계약자가 전적으로 책임지며, 회사의 라이더 신원·연령 확인 여부와 관계없습니다.
B33: 12대 중과실·면책사고 | D33: 신호위반·중앙선침범·무면허·음주운전 등 12대 중과실 또는 보험약관상 면책사항(고의·약물·범죄·운행자 범위 외 운전·도난중 운행 등)에 해당하는 사고로 회사에 보험사 구상금이 청구되는 경우, 계약자는 통보 후 7일 이내에 전액 변제하여야 합니다.
B34: 미변제 시 즉시 처리 | D34: 위 구상금을 7일 이내 변제하지 아니하는 경우 본 계약은 자동 해지되고, 회사는 차량을 즉시 회수하며, 보증금은 반환하지 아니합니다(위약금·손해배상금은 별도 청구).
B35: 1. 본 계약에 따른 모든 대금(할부금·보증금·부대비용 등)의 수납 업무는 포어스바이크(유)가 대행하며, 세금계산서는 한국모터사이클리스 유한회사 명의로 발행됩니다. 타 계좌 입금 시 입금 확인이 불가합니다.
B36: 2. 계약 취소·중도 해지 시 계약자는 이륜차 및 배달통·슬라이더 등 무상 지원 비품을 회사가 지정하는 장소로 반납하여야 하며, 보증금은 반환되지 아니하고 위약금과는 별도로 회수비용(출장비·운송비·원상복구비)은 계약자가 부담합니다.
B37: 3. 보증금 지급 유예 기간 내 미지급으로 계약이 자동 해지되는 경우, 계약자는 차량 반환과 동시에 (1) 인도일부터 반환일까지의 일할 사용료, (2) 감가손실액, (3) 등록비·번호판·보험료 등 회사가 이미 지출한 부대비용을 배상합니다.
B38: 4. 세금계산서 또는 현금영수증은 회사 명의로 발행되며, 연대보증인이 있는 경우 연대보증인(사업장)의 사업자등록번호를 기준으로 세금계산서를, 없는 경우 계약자의 주민등록번호를 기준으로 현금영수증을 발급합니다.
B40: ■ 개인(신용)정보 수집·이용, 금융거래정보 제공, 업무위탁 동의
B41: 수집·이용 목적 | D41: 거래관계 설정·유지, 상품 제공, 법령상 의무 이행, 분쟁 처리, 차량 분실 방지, 사고 대응, 보험사고 처리, 운전자 확인 및 보험연령 검증, 채권 관리 등 계약 이행 전반
B42: 수집 항목 | D42: 계약자 — 성명(실명)·주민등록번호·휴대전화번호·이메일·현주소·신분증 정보·거래카드·계좌 정보·차량 위치정보(FMS 수집 포함) 연대보증인(지정 시) — 사업장 상호·사업자번호·주소·연락처·이메일, 대표자 성명·주민등록번호·휴대전화번호·주소
B43: 보유·이용 기간 | D43: 수집·이용 목적 달성 후 파기. 단, 전자상거래법 등 관련 법령에 따라 계약·결제 기록 5년, 채권 관리 기록 5년, 불량이용자 재가입 방지 기록 해지 후 1년 보존
B44: 금융거래정보 제공 | D44: 신용카드·자동이체 등록·해지 시까지 수납기관(및 결제대행사)에 거래정보 제공 (금융실명법에 따라 동의)
B45: 자동이체 동의 | D45: 매월 발생하는 이륜차 할부금, 보증금, 위약금, 과태료, 범칙금, 보험사 구상금 등을 신용카드 자동승인 또는 계좌 자동이체로 출금 거래 신청
B46: 업무위탁 내역 | D46: 협력사(공급·운송·출고 정보), 수납대행사 포어스바이크(유)(대금 수납·채권관리), 배달대행사(고객정보), 차량등록소(등록 사무), 효성에프엠에스(자동이체)
...

Sheet 이용약관
B1: 이륜차 할부판매 계약 이용약관
B3: 제1조 (목적) | D3: ② 결제방법이란, 회사가 안내한 수납대행사 은행계좌로 한국은행 발행 통화를 지급하거나 결제 수
B4: 이 약관은 한국모터사이클리스 유한회사(이하 "회사")와 본 계약을 체결한 계약자(이하 "계약자")간 | D4: 단을 통해 납부하는 것을 의미한다.
B5: 의 이륜차 할부판매에 관한 권리·의무를 규정함을 목적으로 한다. | D5: ③ 매도인의 가격 인상, 정부 정책 등 불가피한 사정으로 할부금이 변동될 경우 회사는 계약자에게 개
D6: 별 통지하며, 계약자는 이륜차 출고 이전까지 계약을 취소할 수 있다.
B7: 제2조 (용어의 정의) | D7: ④ 이륜차의 도난·멸실·훼손으로 운행이 불가능한 사유가 발생하더라도 계약자는 할부금 지급 의무를
B8: ① "할부판매 계약"이란, 계약자가 요청한 기종의 이륜차를 회사가 판매하고 계약자가 그 대금을 일 | D8: 거부할 수 없다.
B9: 정 기간에 걸쳐 분할 지급하는 매매계약을 말한다. | D9: ⑤ 납부주기 변경으로 할부금이 조정되는 경우 최초 계약 당시의 단가표 기준에 따라 산정·적용한다.
B10: ② "이륜차"란, 회사가 계약자의 요청에 따라 본 계약서에 특정한 이륜차를 말하며, 인도 시 부착된 | D10: ⑥ 본 계약상 모든 미납금(할부금·과태료·범칙금·구상금·취·등록세·수리비·위약금·손해배상금 등)에 대하여
B11: 부속품 및 장착물을 포함한다. | D11: 연체·미납이 발생하는 경우, 회사는 계약자의 별도 동의 없이 (1) 신용정보집중기관에 채무불이행 사실을
B12: ③ "계약기간"이란, 계약자가 본 계약에 따라 이륜차를 인도받아 사용하는 기간을 말한다. | D12: 등록하거나, (2) 신용정보업체 등 채권추심 전문기관에 채권추심을 위임할 수 있다. 수납대행사인 포어스
D13: 바이크 유한회사는 회사를 대리하여 계약자에게 미납금 납부 독촉을 할 수 있다.
D14: ⑦ 계약자가 가맹중인 배달플랫폼 본사와 회사 간의 제휴계약이 체결되어 있는 경우, 해당 플랫폼사의
D15: 페이를 통하여 할부금·과태료 등의 납부가 가능하다. 단, (1) 계약자와 플랫폼사 간 가맹계약 종료, (2)
D16: 회사와 플랫폼 간 제휴계약 종료, (3) 플랫폼사의 페이가 72시간 연속으로 회사가 요청하는 금액만큼
D17: 회사 계좌로 출금되지 아니한 경우, 일차감 프로그램은 즉시 중단되고 본 조 제1항·제2항에 따라
B18: ④ "보증금"이란, 할부금 지급 및 본 계약상 채무이행을 담보하기 위해 계약자가 회사에 납부하는 금 | D18: 결제방법이 즉시 변경된다.
B19: 원을 말하며, 계약기간 만료 시 계약자가 모든 채무를 이행 완료한 경우 반환한다. | D19: 제8조 (지연손해금 및 반환지연금)
B20: ⑤ "계약자"는 본 계약 1면에 "계약자"로 기재된 라이더 본인을 말하며, 본 계약상 주채무자이자 본 | D20: ① 계약자가 약정 금액을 기한 내에 이행하지 않는 경우 위약금이 발생하며, 계약자는 회사의 청구일
B21: 계약 차량을 실제 운행하는 자이다. | D21: 로부터 5일 이내에 지급하여야 한다.
D22: ② 지연손해금 계산식: 지연손해금 = 연체금액 × 경과일수 × 연 20%
D23: ③ 반환지연금은 계약 만료·해지에도 불구하고 계약자가 이륜차를 반환하지 않고 점유·사용을 계속
D24: 하는 경우 발생하며, 계산식은 다음과 같다. ㆍ반환지연금 = 1일 사용료 × 경과일수 × 연20%
B25: ⑥ "위약금"이란, 계약자의 귀책사유로 주문 취소 또는 중도 해지 시 회사에 지급하여야 하는 금액을 | D25: ④ 지연손해금과 반환지연금은 회사의 손해배상청구와 별도로 부과될 수 있다.
B26: 말한다. | D26: ⑤ 연체·미납이 발생하는 경우 회사는 계약자의 별도 동의 없이 해당 채무를 신용정보집중기관
B27: ⑦ "지연손해금"이란, 계약자가 할부금·위약금·과태료 등의 납부를 지체한 경우 발생하는 추가 비용 | D27: 에 등록하거나 신용정보업체에 채권추심을 의뢰할 수 있다.
B28: 을 말한다.
B29: ⑧ "계약이관"이란, 계약자가 본 계약상의 권리와 의무를 제3자에게 승계하는 것을 말한다.
B30: ⑨ "구상금"이란, 본 계약 차량 운행 중 발생한 사고로 보험사 또는 제3자가 회사에 청구하는 금액 일
B31: 체를 말한다.
B32: ⑩ "미수선처리"란, 사고 발생 시 계약자가 차량을 수리하지 아니하고 임의로 수리비 전부 또는 일부 금액을 현금으로 지급받는 행위를 말한다.
B33: ⑪ "플랫폼 일차감 프로그램"이란, 계약자가 가맹중인 배달플랫폼 본사와 회사 간의 제휴계약이 체결되어 있는 경우 해당 플랫폼사의 페이를 통해 할부금·과태료 등 납부가 가능한 전산 시스템을 말한다.
B35: 제3조 (서류 제출 및 이륜차 인도)
B36: ① 계약자는 본 계약 체결에 필요한 서류를 회사에 제출하여야 하며, 보완 요구에도 성실히 응한다.
B37: 제출된 서류는 어떠한 경우에도 반환하지 아니한다.
B38: ② 회사는 청구시작일부터 지정 장소에 이륜차를 인도하며, 해당 날짜부터 계약이 개시된다. 인도 이
B39: 후에는 계약자는 이륜차의 하자·결함을 이유로 할부금 지급의무를 거부할 수 없다.
B41: 제4조 (소유권 유보 및 이전)
B42: ① 본 계약에 따른 이륜차의 소유권은 계약자가 모든 채무를 전액 이행할 때까지 회사에 유보된다.
B43: ② 인수형 계약의 경우, 계약자가 모든 채무를 완전히 이행한 때 회사는 회사의 내부 행정 절차에 따라 | D43: 제9조 (운행자성 및 운행지배)
...

Sheet 별지_구상금
B2: 구상금 관련 특약 확인서
B3: 본 별지는 이륜차 할부판매 계약에 부속되며 본 계약서 본문과 동일한 효력을 가집니다.
B5: 본인은 본 계약과 관련하여 발생할 수 있는 "구상금"의 책임 범위, 변제 기한, 미변제 시 회사의 조치 사항에 대하여 별도로 충분히 설명듣고 이해하였으며, 아래 내용 전부에 동의합니다.
B7: 제1조 구상금의 정의
B8: "구상금"이란 본 계약 차량의 운행 중 발생한 사고로 보험사 또는 제3자가 회사에 청구하는 금액 일체를 말하며, 원금·지연이자·소송비용·변호사비 등 회사가 그와 관련하여 지출한 모든 비용을 포함한다.
B10: 제2조 구상금이 발생하는 주요 사유
B11: 다음 각 호에 해당하는 사고로 회사가 구상금을 청구받는 경우 그 책임은 전적으로 계약자에게 있다.
B12: ① | C12: 운행자성 | D12: 회사는 차량 소유자이나 자동차손해배상보장법상 운행자가 아니다. 운행자성은 전적으로 계약자에게 있으며, 보험사가 회사에 청구하는 구상금은 계약자가 전액 부담한다.
B13: ② | C13: 사고 미고지 위반 | D13: 사고 발생 시 즉시 회사에 고지하지 아니하거나 지연·허위 고지로 발생하는 미보장 손해와 회사에 청구되는 구상금 일체를 계약자가 부담한다.
B14: ③ | C14: 보험연령 미달자 운전 | D14: 보험연령 미달자가 본 차량을 운행하여 발생한 사고·손해·구상금은 회사의 신원·연령 확인 여부와 관계없이 계약자가 책임진다.
B15: ④ | C15: 12대 중과실·면책사고 | D15: 신호위반·중앙선침범 등 12대 중과실 또는 보험약관상 면책사항에 해당하는 사고로 발생한 구상금은 계약자가 전액 부담한다.
B16: ⑤ | C16: 무면허·음주·약물 운전 | D16: 무면허·음주·약물 영향 하의 운전 및 운전자 자격 미충족자의 운행으로 발생한 사고·구상금은 계약자가 전적으로 책임진다.
B17: ⑥ | C17: 보험 보장 한도 초과 | D17: 대물배상 한도 초과분·대인배상Ⅱ 한도 초과분 등 보험사 보장 한도를 초과하는 손해는 계약자가 전액 부담한다.
B18: ⑦ | C18: 기타 보험약관상 면책사유 | D18: 운전자 범위 위반·사고 후 도주·고의 사고·유상운송 부적합 보험·차량 무단 양도·전대·무보험 운행 등 보험약관상 면책사유에 해당하는 일체의 손해를 계약자가 전적으로 책임진다.
B20: 제3조 구상금의 변제 기한
B21: 회사가 보험사 또는 제3자로부터 구상금을 청구받았다는 사실을 계약자에게 통보한 날로부터 7일 이내에, 계약자는 구상금 전액 및 회사가 지출한 변호사비·소송비 일체를 회사에 변제하여야 한다.
B23: 제4조 미변제 시 즉시 처리
B24: 제3조의 변제 기한 내에 계약자가 구상금을 변제하지 아니하는 경우 본 계약은 사전 통지·최고 없이 자동 해지되며, 회사는 다음 각 호의 조치를 동시에 또는 순차적으로 취할 수 있다.
B25: ① | C25: 차량 즉시 회수 | D25: 회수에 소요된 일체의 비용(출장비·운송비·원상복구비 포함)은 계약자가 부담한다.
B26: ② | C26: 보증금 전액 미반환 | D26: 어떠한 사유로도 보증금은 반환되지 아니한다.
B27: ③ | C27: 위약금·손해배상금 청구 | D27: 위약금 = 보증금 + (잔여기간 총 할부금 × 20%) 산식에 따라 부과하며, 손해배상금도 별도 청구한다.
B28: ④ | C28: 연 15% 지연손해금 | D28: 미변제 금액에 대하여 연 15%의 지연손해금을 변제일까지 가산한다.
B29: ⑤ | C29: 신용정보 등록·채권추심 | D29: 별도 동의 없이 신용정보집중기관에 채무불이행 사실을 등록하거나 채권추심을 의뢰할 수 있다.
B30: ⑥ | C30: 민·형사상 법적 조치 | D30: 계약자에 대하여 민·형사상 모든 법적 조치를 취할 수 있다.
B33: 본인은 위 특약 내용(제1조 ~ 제4조) 전부를 충분히 설명듣고 이해하였으며, 본 특약에 동의함을 확인합니다.
B35: 계약자 | C35: =IFERROR(IF(계약서!G9="","",계약서!G9),"") | I35: (인)
B37: 공급자 | C37: 한국모터사이클리스 유한회사 | I37: (인)
