Workbook

Sheet 계약리스트
A1: 계약번호 | B1: 계약일자 | C1: 차종 | D1: 차대번호 | E1: 차량번호 | F1: 색상 | G1: 일사용료 | H1: 사용일수 | I1: 보증금 | J1: 라이더명 | K1: 라이더 주민번호 | L1: 라이더 연락처 | M1: 라이더 이메일 | N1: 라이더 주소 | O1: 라이더 본인명의 은행 | P1: 라이더 본인명의 계좌번호 | Q1: 라이더 업종/담당업무 | R1: 사업장 업체명 | S1: 사업장 사업자번호 | T1: 사업장 대표자명 | U1: 사업장 대표자 주민번호 | V1: 사업장 대표자 연락처 | W1: 사업장 주소 | X1: 사업장 대표자 주소 | Y1: 사업장 이메일 | Z1: 계약유형 | AA1: 상품유형 | AB1: 납입방법 | AC1: 납입계좌 | AD1: 요금결제일
A2: 1 | B2: 2026-04-23 | C2: PCX125 | D2: MLHJF81H2ST000001 | E2: 서울바1234 | F2: 블랙 | G2: 12000 | H2: 365 | I2: 300000 | J2: 홍길동 | K2: 900101-1234567 | L2: 010-1234-5678 | M2: rider@example.com | N2: 서울시 강남구 테헤란로 123 | O2: 국민은행 | P2: 123456-78-901234 | Q2: 배달 라이더 | R2: (주)퀵배달 | S2: 123-45-67890 | T2: 김대표 | U2: 700101-1234567 | V2: 010-9876-5432 | W2: 서울시 강남구 봉은사로 100 | X2: 서울시 송파구 잠실동 200 | Y2: biz@example.com | Z2: 할부 판매 | AA2: 인수형 | AB2: 계좌이체 | AC2: 기업은행 929-028519-04-010 | AD2: 월2회(15일, 말일)

Sheet 계약서
L1: 계약번호입력→
B2: 이륜차 할부판매 계약서 | L2: 1
B3: 한국모터사이클리스 유한회사 | F3: 계약번호 | I3: =IFERROR(TEXT($L$2,"0000"),"") -> 0001
B5: ■ 차량 정보
B6: 차종 | C6: =IFERROR(IF(VLOOKUP($L$2,계약리스트!$A$2:$AD$10000,3,0)="","",VLOOKUP($L$2,계약리스트!$A$2:$AD$10000,3,0)),"") -> PCX125 | E6: 차량번호 | F6: =IFERROR(IF(VLOOKUP($L$2,계약리스트!$A$2:$AD$10000,5,0)="","",VLOOKUP($L$2,계약리스트!$A$2:$AD$10000,5,0)),"") -> 서울바1234 | H6: 색상 | I6: =IFERROR(IF(VLOOKUP($L$2,계약리스트!$A$2:$AD$10000,6,0)="","",VLOOKUP($L$2,계약리스트!$A$2:$AD$10000,6,0)),"") -> 블랙
B7: 차대번호 | C7: =IFERROR(IF(VLOOKUP($L$2,계약리스트!$A$2:$AD$10000,4,0)="","",VLOOKUP($L$2,계약리스트!$A$2:$AD$10000,4,0)),"") -> MLHJF81H2ST000001 | E7: 정비여부 | F7: 미포함 | H7: 계약일자 | I7: =IFERROR(IF(VLOOKUP($L$2,계약리스트!$A$2:$AD$10000,2,0)="","",VLOOKUP($L$2,계약리스트!$A$2:$AD$10000,2,0)),"") -> 2026-04-23
B9: ■ 계약자
B10: 성명 | C10: =IFERROR(IF(VLOOKUP($L$2,계약리스트!$A$2:$AD$10000,10,0)="","",VLOOKUP($L$2,계약리스트!$A$2:$AD$10000,10,0)),"") -> 홍길동 | E10: 주민등록번호 | F10: =IFERROR(IF(VLOOKUP($L$2,계약리스트!$A$2:$AD$10000,11,0)="","",VLOOKUP($L$2,계약리스트!$A$2:$AD$10000,11,0)),"") -> 900101-1234567 | H10: 연락처 | I10: =IFERROR(IF(VLOOKUP($L$2,계약리스트!$A$2:$AD$10000,12,0)="","",VLOOKUP($L$2,계약리스트!$A$2:$AD$10000,12,0)),"") -> 010-1234-5678
B11: 주소 | C11: =IFERROR(IF(VLOOKUP($L$2,계약리스트!$A$2:$AD$10000,14,0)="","",VLOOKUP($L$2,계약리스트!$A$2:$AD$10000,14,0)),"") -> 서울시 강남구 테헤란로 123
B12: ※ 제출 서류 : 라이더 신분증 사본
B14: ■ 연대보증인
B15: 업체명 | C15: =IFERROR(IF(VLOOKUP($L$2,계약리스트!$A$2:$AD$10000,18,0)="","",VLOOKUP($L$2,계약리스트!$A$2:$AD$10000,18,0)),"") -> (주)퀵배달 | E15: 사업자번호 | F15: =IFERROR(IF(VLOOKUP($L$2,계약리스트!$A$2:$AD$10000,19,0)="","",VLOOKUP($L$2,계약리스트!$A$2:$AD$10000,19,0)),"") -> 123-45-67890 | H15: 이메일 | I15: =IFERROR(IF(VLOOKUP($L$2,계약리스트!$A$2:$AD$10000,25,0)="","",VLOOKUP($L$2,계약리스트!$A$2:$AD$10000,25,0)),"") -> biz@example.com
B16: 대표자명 | C16: =IFERROR(IF(VLOOKUP($L$2,계약리스트!$A$2:$AD$10000,20,0)="","",VLOOKUP($L$2,계약리스트!$A$2:$AD$10000,20,0)),"") -> 김대표 | E16: 대표자 주민번호 | F16: =IFERROR(IF(VLOOKUP($L$2,계약리스트!$A$2:$AD$10000,21,0)="","",VLOOKUP($L$2,계약리스트!$A$2:$AD$10000,21,0)),"") -> 700101-1234567 | H16: 대표자 연락처 | I16: =IFERROR(IF(VLOOKUP($L$2,계약리스트!$A$2:$AD$10000,22,0)="","",VLOOKUP($L$2,계약리스트!$A$2:$AD$10000,22,0)),"") -> 010-9876-5432
B17: 업체 주소 | C17: =IFERROR(IF(VLOOKUP($L$2,계약리스트!$A$2:$AD$10000,23,0)="","",VLOOKUP($L$2,계약리스트!$A$2:$AD$10000,23,0)),"") -> 서울시 강남구 봉은사로 100
B18: 대표자 주소 | C18: =IFERROR(IF(VLOOKUP($L$2,계약리스트!$A$2:$AD$10000,24,0)="","",VLOOKUP($L$2,계약리스트!$A$2:$AD$10000,24,0)),"") -> 서울시 송파구 잠실동 200
B19: ="※ 제출 서류 : 사업자등록증 사본, 대표자 신분증 사본 | 보증 기한 : "&VALUE(SUBSTITUTE(I22,"일",""))+365&"일 | 보증 한도 : 전체 이용료의 130%" -> ※ 제출 서류 : 사업자등록증 사본, 대표자 신분증 사본 | 보증 기한 : 730일 | 보증 한도 : 전체 이용료의 130%
B21: ■ 계약 조건
B22: 계약유형 | C22: =IFERROR(IF(VLOOKUP($L$2,계약리스트!$A$2:$AD$10000,26,0)="","",VLOOKUP($L$2,계약리스트!$A$2:$AD$10000,26,0)),"") -> 할부 판매 | E22: 상품유형 | F22: =IFERROR(IF(VLOOKUP($L$2,계약리스트!$A$2:$AD$10000,27,0)="","",VLOOKUP($L$2,계약리스트!$A$2:$AD$10000,27,0)),"") -> 인수형 | H22: 할부판매 기간 | I22: =IFERROR(VLOOKUP($L$2,계약리스트!$A$2:$AD$10000,8,0)&"일","") -> 365일
B23: 일사용료 (VAT포함) | C23: =IFERROR(TEXT(VLOOKUP($L$2,계약리스트!$A$2:$AD$10000,7,0),"#,##0")&" 원","") -> 12,000 원 | E23: 보증금 | F23: =IFERROR(TEXT(VLOOKUP($L$2,계약리스트!$A$2:$AD$10000,9,0),"#,##0")&" 원","") -> 300,000 원 | H23: 요금결제일 | I23: =IFERROR(IF(VLOOKUP($L$2,계약리스트!$A$2:$AD$10000,30,0)="","",VLOOKUP($L$2,계약리스트!$A$2:$AD$10000,30,0)),"") -> 월2회(15일, 말일)
B24: 납입방법 | C24: 계좌이체 | E24: 청구시작일 | F24: 차량 인도일부터
B25: 납입계좌 | C25: 기업은행 929-028519-04-010
B27: ■ 회사 정보 (공급자)
B28: 상호 | C28: 한국모터사이클리스 유한회사 | E28: 사업자번호 | F28: 104-86-62883 | H28: 대표이사 | I28: 김현수
B29: 주소 | C29: 강원특별자치도 춘천시 춘천로 188, 201호, 211호-에이66호 | G29: 고객센터 | H29: 010-2730-7845
B31: ■ 주요 확인사항 (서명 전 필독)
B32: 1. 본 계약에 따른 모든 대금(할부금·보증금·부대비용 등)의 수납 및 세금계산서 발행 업무는 포어스바이크(유)가 대행하며, 타 계좌 입금 시 입금 확인이 불가합니다.
B33: 2. 계약 취소·중도 해지 시 보증금은 반환되지 아니하며, 위약금과는 별도로 회수비용(출장비·운송비·원상복구비)은 계약자가 부담합니다.
B34: 3. 보증금 지급 유예 기간 내 미지급으로 계약이 자동 해지되는 경우, 계약자는 차량 반환과 동시에 (1) 인도일부터 반환일까지의 일할 사용료, (2) 감가손실액, (3) 등록비·번호판·보험료 등 회사가 이미 지출한 부대비용을 배상합니다.
B35: 4. 배달통·슬라이더 등 무상 지원 비품은 계약 취소·중도 해지 시 안내 장소로 반납하여야 합니다.
B36: 5. 세금계산서는 회사 명의로 발행되며, 본 계약서에 기재된 연대보증인(사업장)의 사업자등록번호를 기준으로 발급됩니다.
B38: ■ 개인(신용)정보 수집·이용, 금융거래정보 제공, 업무위탁 동의
B39: 수집·이용 목적 | D39: 거래관계 설정·유지, 상품 제공, 법령상 의무이행, 분쟁처리, 민원처리, 차량 분실 방지, 사고 대응, 서비스 개선, 통계 분석 등 계약 이행 전반
B40: 수집 항목 | D40: 성명(실명), 주민등록번호, 휴대전화번호, 이메일, 현주소, 근무지, 신분증 정보, 거래카드·계좌 정보, 차량 위치정보(FMS 수집 포함)
B41: 보유·이용 기간 | D41: 수집·이용 목적 달성 후 파기. 단, 전자상거래법 등 관련 법령에 따라 계약·결제 기록은 5년 보존, 불량이용자 재가입 방지 등 목적 기록은 해지 후 1년 보존
B42: 금융거래정보 제공 | D42: 신용카드·자동이체 등록·해지 시까지 수납기관(및 결제대행사)에 거래정보 제공 (금융실명법에 따라 동의)
B43: 자동이체 동의 | D43: 매월 발생하는 이륜차 임대료, 보증금, 위약금, 과태료, 범칙금 등을 신용카드 자동승인 또는 계좌 자동이체로 출금 거래 신청
B44: 업무위탁 내역 | D44: 협력사(공급·운송·출고 정보), 수납대행사 포어스바이크(유)(대금 수납·세금계산서·채권관리), 배달대행사(고객정보), 차량등록소(등록 사무), 효성에프엠에스(자동이체)
B45: 상기 "개인(신용)정보 수집·이용·제공 동의", "금융거래정보 제공 동의", "업무위탁 동의"에 대하여 □ 동의안함 □ 전부 동의함
B47: ■ 계약 체결
B48: 본인은 본 이륜차 할부판매 계약서와 별지 이용약관의 내용을 전부 설명 듣고 확인하였으며, 본 계약에 따른 권리·의무와 제반 동의 사항에 이의 없이 동의합니다.
...

Sheet 이용약관
B1: [별지] 이륜차 할부판매 계약 이용약관
B3: 제1조 (목적) | D3: ② 전항의 유예기간 내 지급이 이루어지지 않을 경우 본 계약은 자동 해지되며, 계약자는
B4: 이 약관은 한국모터사이클리스 유한회사(이하 "회사")와 본 계약을 체결한 계약자(라이더, | D4: 즉시 이륜차를 반환함과 동시에 (1) 인도일부터 반환일까지의 일할 사용료, (2) 이륜차의
B5: 이하 "계약자") 간의 이륜차 할부판매에 관한 권리·의무를 규정함을 목적으로 한다. | D5: 감가손실액, (3) 차량 등록비·번호판 비용·보험료 등 회사가 이미 지출한 부대비용 일체를
D6: 회사에 배상하여야 한다.
B7: 제2조 (용어의 정의) | D7: ③ 보증금은 계약기간 만료 및 계약자가 모든 채무를 이행한 경우 수납대행사를 통해 반환
B8: ① "할부판매 계약"이란, 계약자가 요청한 기종의 이륜차를 회사가 판매하고 계약자가 그 | D8: 한다. 다만, 미납 과태료·수리비 등이 확인될 수 있으므로 계약기간 만료일로부터 1개월이
B9: 대금을 일정 기간에 걸쳐 분할 지급하는 매매계약을 말한다. | D9: 경과한 이후에 반환한다.
B10: ② "이륜차"란, 회사가 계약자의 요청에 따라 본 계약서에 특정한 이륜차를 말하며, 인도 시 | D10: ④ 반환된 이륜차 상태에 따라 보증금에서 수리비를 공제하며, 수리비가 보증금을 초과하면
B11: 부착된 부속품 및 장착물을 포함한다. | D11: 계약자는 차액을 추가 납부하여야 한다.
B12: ③ "계약기간"이란, 계약자가 본 계약에 따라 이륜차를 인도받아 사용하는 기간을 말한다. | D12: ⑤ 미납 과태료·범칙금은 보증금에서 공제하고 잔액을 반환하며, 초과분은 계약자가 추가
B13: ④ "보증금"이란, 할부금 지급 및 본 계약상 채무이행을 담보하기 위해 계약자가 회사에 | D13: 납부하여야 한다.
B14: 납부하는 금원을 말하며, 계약기간 만료 시 계약자가 모든 채무를 이행 완료한 경우 | D14: ⑥ 계약이 중도 해지된 경우 계약자는 어떠한 사유로도 납부한 보증금 및 계약금을 반환
B15: 반환한다. | D15: 받을 수 없다.
B16: ⑤ "계약자(라이더)"는 본 계약 제1면에 "계약자(라이더)"로 기재된 라이더 본인을 말하며,
B17: 본 계약상 주채무자이다. | D17: 제8조 (할부금 및 기타 지급금)
B18: ⑥ "연대보증인(사업장)"은 본 계약 제1면에 기재된 사업장 및 그 대표자를 말하며, | D18: ① 계약자는 계약서에 기재된 할부금 및 운행 관련 제 비용을 공휴일과 무관하게 정해진
B19: 계약자와 연대하여 본 계약상 채무를 부담함과 동시에 세금계산서 수취 대상을 겸한다. | D19: 결제일에 수납대행사 계좌로 납부하여야 한다.
B20: ⑦ "위약금"이란, 계약자의 귀책사유로 주문 취소 또는 중도 해지 시 회사에 지급하여야 | D20: ② 결제방법이란, 회사가 안내한 수납대행사 은행계좌로 한국은행 발행 통화를 지급하거나
B21: 하는 금액을 말한다. | D21: 결제 수단을 통해 납부하는 것을 의미한다.
B22: ⑧ "지연손해금"이란, 계약자가 할부금·위약금·과태료 등의 납부를 지체한 경우 발생하는 | D22: ③ 매도인의 가격 인상, 정부 정책 등 불가피한 사정으로 할부금이 변동될 경우 회사는 계약
B23: 추가 비용을 말한다. | D23: 자에게 개별 통지하며, 계약자는 이륜차 출고 이전까지 계약을 취소할 수 있다.
B24: ⑨ "계약이관"이란, 계약자가 본 계약상의 권리와 의무를 제3자에게 승계하는 것을 말한다. | D24: ④ 이륜차의 도난·멸실·훼손으로 운행이 불가능한 사유가 발생하더라도 계약자는 할부금
D25: 지급의무를 거부할 수 없다.
B26: 제3조 (서류 제출 및 보완) | D26: ⑤ 납부주기 변경으로 할부금이 조정되는 경우 최초 계약 당시의 단가표 기준에 따라
B27: ① 계약자는 본 계약 체결에 필요한 서류를 회사에 제출하여야 하며, 추후 보완 요구에도 | D27: 산정·적용한다.
B28: 성실히 응하여야 한다. | D28: ⑥ 회사는 연체된 할부금·위약금 등 본 계약상 채권의 회수 및 추심 업무를 수납대행사(포어
B29: ② 제출된 서류는 어떠한 경우에도 반환하지 아니한다. | D29: 스바이크 유한회사)에 위임하며, 수납대행사는 회사를 대리하여 계약자에게 독촉·추심
D30: 할 수 있다.
B31: 제4조 (소유권 유보)
B32: ① 본 계약에 따른 이륜차의 소유권은 계약자가 모든 채무를 전액 이행할 때까지 회사에 | D32: 제9조 (지연손해금 및 반환지연금)
B33: 유보된다. | D33: ① 계약자가 약정 금액을 기한 내에 이행하지 않는 경우 위약금이 발생하며, 계약자는 회사
B34: ② 계약자가 계약기간 동안 할부금을 성실히 납부하고 본 계약상 모든 채무를 완전히 이행한 | D34: 의 청구일로부터 5일 이내에 지급하여야 한다.
B35: 경우, 회사는 회사의 내부 행정 절차에 따라 이륜차의 소유권을 계약자에게 이전한다. | D35: ② 지연손해금 계산식: 지연손해금 = 연체금액 × 경과일수 × 연 20%
D36: ③ 반환지연금은 계약 만료·해지에도 불구하고 계약자가 이륜차를 반환하지 않고 점유·사용
B37: 제5조 (계약자의 책임) | D37: 을 계속하는 경우 발생하며, 계산식은 다음과 같다
B38: ① 계약자는 선량한 관리자의 주의로 이륜차를 유지·관리하여야 하며, 운행 중 발생하는 | D38: ㆍ반환지연금 = 1일 사용료 × 경과일수 × 연 20%
B39: 모든 사고에 대해 책임을 부담한다. 회사가 소유권을 보유하더라도 운행자성이 없으므로 | D39: ④ 지연손해금과 반환지연금은 회사의 손해배상청구와 별도로 부과될 수 있다.
B40: 인적·물적 관리책임은 전적으로 계약자에게 있다. | D40: ⑤ 연체·미납이 발생하는 경우 회사는 계약자의 별도 동의 없이 해당 채무를 신용정보집중
B41: ② 계약자는 계약기간 중 임의로 타부착물을 장착하거나 이륜차의 구조를 변경할 수 없다. | D41: 기관에 등록하거나 신용정보업체에 채권추심을 의뢰할 수 있다.
...
