Workbook

Sheet 계약리스트
A1: 계약번호 | B1: 계약일자 | C1: 차종 | D1: 차대번호 | E1: 차량번호 | F1: 색상 | G1: 일사용료 | H1: 사용일수 | I1: 보증금 | J1: 라이더명 | K1: 라이더 주민번호 | L1: 라이더 연락처 | M1: 라이더 이메일 | N1: 라이더 주소 | O1: 라이더 본인명의 은행 | P1: 라이더 본인명의 계좌번호 | Q1: 라이더 업종/담당업무 | R1: 사업장 업체명 | S1: 사업장 사업자번호 | T1: 사업장 대표자명 | U1: 사업장 대표자 주민번호 | V1: 사업장 대표자 연락처 | W1: 사업장 주소 | X1: 사업장 대표자 주소 | Y1: 사업장 이메일 | Z1: 계약유형 | AA1: 상품유형 | AB1: 납입방법 | AC1: 납입계좌 | AD1: 요금결제일
A2: 1 | B2: 2026-04-23 | C2: PCX125 | D2: MLHJF81H2ST000001 | E2: 서울바1234 | F2: 블랙 | G2: 12000 | H2: 365 | I2: 300000 | J2: 홍길동 | K2: 900101-1234567 | L2: 010-1234-5678 | M2: rider@example.com | N2: 서울시 강남구 테헤란로 123 | O2: 국민은행 | P2: 123456-78-901234 | Q2: 배달 라이더 | R2: (주)퀵배달 | S2: 123-45-67890 | T2: 김대표 | U2: 700101-1234567 | V2: 010-9876-5432 | W2: 서울시 강남구 봉은사로 100 | X2: 서울시 송파구 잠실동 200 | Y2: biz@example.com | Z2: 할부 판매 | AA2: 인수형 | AB2: 계좌이체 | AC2: 기업은행 929-028519-04-010 | AD2: 월2회(15일, 말일)

Sheet 계약서
L1: 계약번호입력→
B2: 이륜차 할부판매 계약서 | L2: 1
B3: 한국모터사이클리스 유한회사 | F3: 계약번호 | I3: =IFERROR(TEXT($L$2,"0000"),"") -> 0001
B5: ■ 차량 정보
B6: 차종 | C6: =IFERROR(IF(VLOOKUP($L$2,계약리스트!$A$2:$AD$10000,3,0)="","",VLOOKUP($L$2,계약리스트!$A$2:$AD$10000,3,0)),"") -> PCX125 | E6: 차량번호 | F6: =IFERROR(IF(VLOOKUP($L$2,계약리스트!$A$2:$AD$10000,5,0)="","",VLOOKUP($L$2,계약리스트!$A$2:$AD$10000,5,0)),"") -> 서울바1234 | H6: 색상 | I6: =IFERROR(IF(VLOOKUP($L$2,계약리스트!$A$2:$AD$10000,6,0)="","",VLOOKUP($L$2,계약리스트!$A$2:$AD$10000,6,0)),"") -> 블랙
B7: 차대번호 | C7: =IFERROR(IF(VLOOKUP($L$2,계약리스트!$A$2:$AD$10000,4,0)="","",VLOOKUP($L$2,계약리스트!$A$2:$AD$10000,4,0)),"") -> MLHJF81H2ST000001 | E7: 정비여부 | F7: 미포함 | H7: 계약일자 | I7: =IFERROR(IF(VLOOKUP($L$2,계약리스트!$A$2:$AD$10000,2,0)="","",VLOOKUP($L$2,계약리스트!$A$2:$AD$10000,2,0)),"") -> 2026-04-23
B9: ■ 계약자(라이더) — 본 계약상 주채무자
B10: 성명 | C10: =IFERROR(IF(VLOOKUP($L$2,계약리스트!$A$2:$AD$10000,10,0)="","",VLOOKUP($L$2,계약리스트!$A$2:$AD$10000,10,0)),"") -> 홍길동 | E10: 주민등록번호 | F10: =IFERROR(IF(VLOOKUP($L$2,계약리스트!$A$2:$AD$10000,11,0)="","",VLOOKUP($L$2,계약리스트!$A$2:$AD$10000,11,0)),"") -> 900101-1234567 | H10: 연락처 | I10: =IFERROR(IF(VLOOKUP($L$2,계약리스트!$A$2:$AD$10000,12,0)="","",VLOOKUP($L$2,계약리스트!$A$2:$AD$10000,12,0)),"") -> 010-1234-5678
B11: 이메일 | C11: =IFERROR(IF(VLOOKUP($L$2,계약리스트!$A$2:$AD$10000,13,0)="","",VLOOKUP($L$2,계약리스트!$A$2:$AD$10000,13,0)),"") -> rider@example.com | E11: 업종/담당업무 | F11: =IFERROR(IF(VLOOKUP($L$2,계약리스트!$A$2:$AD$10000,17,0)="","",VLOOKUP($L$2,계약리스트!$A$2:$AD$10000,17,0)),"") -> 배달 라이더
B12: 주소 | C12: =IFERROR(IF(VLOOKUP($L$2,계약리스트!$A$2:$AD$10000,14,0)="","",VLOOKUP($L$2,계약리스트!$A$2:$AD$10000,14,0)),"") -> 서울시 강남구 테헤란로 123
B13: 본인명의 은행 | C13: =IFERROR(IF(VLOOKUP($L$2,계약리스트!$A$2:$AD$10000,15,0)="","",VLOOKUP($L$2,계약리스트!$A$2:$AD$10000,15,0)),"") -> 국민은행 | E13: 본인명의 계좌번호 | F13: =IFERROR(IF(VLOOKUP($L$2,계약리스트!$A$2:$AD$10000,16,0)="","",VLOOKUP($L$2,계약리스트!$A$2:$AD$10000,16,0)),"") -> 123456-78-901234
B14: ※ 제출 서류 : 라이더 신분증 사본, 본인 명의 통장 사본 | 입금은 반드시 본인 명의 계좌에서 이루어져야 함 (입금자명 확인)
B16: ■ 연대보증인(사업장) — 주채무자와 연대하여 채무를 부담 | 세금계산서 수취 대상을 겸함
B17: 업체명 | C17: =IFERROR(IF(VLOOKUP($L$2,계약리스트!$A$2:$AD$10000,18,0)="","",VLOOKUP($L$2,계약리스트!$A$2:$AD$10000,18,0)),"") -> (주)퀵배달 | E17: 사업자번호 | F17: =IFERROR(IF(VLOOKUP($L$2,계약리스트!$A$2:$AD$10000,19,0)="","",VLOOKUP($L$2,계약리스트!$A$2:$AD$10000,19,0)),"") -> 123-45-67890 | H17: 이메일 | I17: =IFERROR(IF(VLOOKUP($L$2,계약리스트!$A$2:$AD$10000,25,0)="","",VLOOKUP($L$2,계약리스트!$A$2:$AD$10000,25,0)),"") -> biz@example.com
B18: 대표자명 | C18: =IFERROR(IF(VLOOKUP($L$2,계약리스트!$A$2:$AD$10000,20,0)="","",VLOOKUP($L$2,계약리스트!$A$2:$AD$10000,20,0)),"") -> 김대표 | E18: 대표자 주민번호 | F18: =IFERROR(IF(VLOOKUP($L$2,계약리스트!$A$2:$AD$10000,21,0)="","",VLOOKUP($L$2,계약리스트!$A$2:$AD$10000,21,0)),"") -> 700101-1234567 | H18: 대표자 연락처 | I18: =IFERROR(IF(VLOOKUP($L$2,계약리스트!$A$2:$AD$10000,22,0)="","",VLOOKUP($L$2,계약리스트!$A$2:$AD$10000,22,0)),"") -> 010-9876-5432
B19: 업체 주소 | C19: =IFERROR(IF(VLOOKUP($L$2,계약리스트!$A$2:$AD$10000,23,0)="","",VLOOKUP($L$2,계약리스트!$A$2:$AD$10000,23,0)),"") -> 서울시 강남구 봉은사로 100
B20: 대표자 주소 | C20: =IFERROR(IF(VLOOKUP($L$2,계약리스트!$A$2:$AD$10000,24,0)="","",VLOOKUP($L$2,계약리스트!$A$2:$AD$10000,24,0)),"") -> 서울시 송파구 잠실동 200
B21: ※ 제출 서류 : 사업자등록증 사본, 대표자 신분증 사본, 업체 통장 사본 | 보증 기한 : 2년 | 보증 한도 : 전체 이용료의 130%
B23: ■ 계약 조건
B24: 계약유형 | C24: =IFERROR(IF(VLOOKUP($L$2,계약리스트!$A$2:$AD$10000,26,0)="","",VLOOKUP($L$2,계약리스트!$A$2:$AD$10000,26,0)),"") -> 할부 판매 | E24: 상품유형 | F24: =IFERROR(IF(VLOOKUP($L$2,계약리스트!$A$2:$AD$10000,27,0)="","",VLOOKUP($L$2,계약리스트!$A$2:$AD$10000,27,0)),"") -> 인수형 | H24: 할부판매 기간 | I24: =IFERROR(VLOOKUP($L$2,계약리스트!$A$2:$AD$10000,8,0)&"일","") -> 365일
B25: 일사용료 (VAT포함) | C25: =IFERROR(TEXT(VLOOKUP($L$2,계약리스트!$A$2:$AD$10000,7,0),"#,##0")&" 원","") -> 12,000 원 | E25: 보증금 | F25: =IFERROR(TEXT(VLOOKUP($L$2,계약리스트!$A$2:$AD$10000,9,0),"#,##0")&" 원","") -> 300,000 원 | H25: 요금결제일 | I25: =IFERROR(IF(VLOOKUP($L$2,계약리스트!$A$2:$AD$10000,30,0)="","",VLOOKUP($L$2,계약리스트!$A$2:$AD$10000,30,0)),"") -> 월2회(15일, 말일)
B26: 납입방법 | C26: =IFERROR(IF(VLOOKUP($L$2,계약리스트!$A$2:$AD$10000,28,0)="","",VLOOKUP($L$2,계약리스트!$A$2:$AD$10000,28,0)),"") -> 계좌이체 | E26: 청구시작일 | F26: 차량 인도일부터
B27: 납입계좌 | C27: =IFERROR(IF(VLOOKUP($L$2,계약리스트!$A$2:$AD$10000,29,0)="","",VLOOKUP($L$2,계약리스트!$A$2:$AD$10000,29,0)),"") -> 기업은행 929-028519-04-010
B29: ■ 회사 정보 (공급자)
B30: 상호 | C30: 한국모터사이클리스 유한회사 | E30: 사업자번호 | F30: 647-86-03800 | H30: 대표이사 | I30: 김현수
B31: 주소 | C31: 경기도 수원시 권선구 입북로59번길 15 | G31: 고객센터 | H31: 010-2730-7845 / 0507-1489-7885
B33: ■ 주요 확인사항 (서명 전 필독)
B34: 1. 본 계약에 따른 모든 대금(할부금·보증금·부대비용 등)의 수납 및 세금계산서 발행 업무는 포어스바이크(유)가 대행하며, 타 계좌 입금 시 입금 확인이 불가합니다.
B35: 2. 계약 취소·중도 해지 시 보증금은 반환되지 아니하며, 위약금과는 별도로 회수비용(출장비·운송비·원상복구비)은 계약자가 부담합니다.
B36: 3. 보증금 지급 유예 기간 내 미지급으로 계약이 자동 해지되는 경우, 계약자는 차량 반환과 동시에 (1) 인도일부터 반환일까지의 일할 사용료, (2) 감가손실액, (3) 등록비·번호판·보험료 등 회사가 이미 지출한 부대비용을 배상합니다.
B37: 4. 배달통·슬라이더 등 무상 지원 비품은 계약 취소·중도 해지 시 안내 장소로 반납하여야 합니다.
B38: 5. 세금계산서는 회사 명의로 발행되며, 본 계약서에 기재된 연대보증인(사업장)의 사업자등록번호를 기준으로 발급됩니다.
B40: ■ 개인(신용)정보 수집·이용, 금융거래정보 제공, 업무위탁 동의
B41: 수집·이용 목적 | D41: 거래관계 설정·유지, 상품 제공, 법령상 의무이행, 분쟁처리, 민원처리, 차량 분실 방지, 사고 대응, 서비스 개선, 통계 분석 등 계약 이행 전반
B42: 수집 항목 | D42: 성명(실명), 주민등록번호, 휴대전화번호, 이메일, 현주소, 근무지, 신분증 정보, 거래카드·계좌 정보, 차량 위치정보(FMS 수집 포함)
B43: 보유·이용 기간 | D43: 수집·이용 목적 달성 후 파기. 단, 전자상거래법 등 관련 법령에 따라 계약·결제 기록은 5년 보존, 불량이용자 재가입 방지 등 목적 기록은 해지 후 1년 보존
B44: 금융거래정보 제공 | D44: 신용카드·자동이체 등록·해지 시까지 수납기관(및 결제대행사)에 거래정보 제공 (금융실명법에 따라 동의)
B45: 자동이체 동의 | D45: 매월 발생하는 이륜차 임대료, 보증금, 위약금, 과태료, 범칙금 등을 신용카드 자동승인 또는 계좌 자동이체로 출금 거래 신청
B46: 업무위탁 내역 | D46: 협력사(공급·운송·출고 정보), 수납대행사 포어스바이크(유)(대금 수납·세금계산서·채권관리), 배달대행사(고객정보), 차량등록소(등록 사무), 효성에프엠에스(자동이체)
B47: 상기 "개인(신용)정보 수집·이용·제공 동의", "금융거래정보 제공 동의", "업무위탁 동의"에 대하여 □ 전부 동의함 □ 일부 동의함 (별지로 특정)
...

Sheet 이용약관
B1: [별지] 이륜차 할부판매 계약 이용약관
B3: 제1조 (목적) | D3: 제12조 (차량 위치정보 등 제공 동의)
B4: 이 약관은 한국모터사이클리스 유한회사(이하 "회사")와 본 계약을 체결한 계약자(라이더, 이하 "계약자") 간의 이륜차 할부판매에 관한 권리·의무를 규정함을 목적으로 한다. | D4: ① 해당 이륜차에는 도난·멸실·분실 위험 방지를 위하여 위치정보 수집 장치가 부착되어 있으며, 계약자는 이를 인지하고 동의한다.
D5: ② 계약자는 실제 운전자 및 운행자로부터 위치정보 수집·이용·제공에 대한 동의를 받아야 하며, 회사 요청 시 동의서 및 관련 위치정보를 지체 없이 제출하여야 한다.
B6: 제2조 (용어의 정의) | D6: ③ 계약자는 위치정보 장치를 임의로 변경·제거·훼손할 수 없다.
B7: ① "할부판매 계약"이란, 계약자가 요청한 기종의 이륜차를 회사가 판매하고 계약자가 그 대금을 일정 기간에 걸쳐 분할 지급하는 매매계약을 말한다. | D7: ④ 회사는 채무불이행, 계약 해지, 회수 절차, 보험사고 처리 등 본 계약 이행·관리에 필요한 범위 내에서만 위치정보를 활용한다.
B8: ② "이륜차"란, 회사가 계약자의 요청에 따라 본 계약서에 특정한 이륜차를 말하며, 인도 시 부착된 부속품 및 장착물을 포함한다.
B9: ③ "계약기간"이란, 계약자가 본 계약에 따라 이륜차를 인도받아 사용하는 기간을 말한다. | D9: 제13조 (이륜차 유지비용 및 제세공과금)
B10: ④ "보증금"이란, 할부금 지급 및 본 계약상 채무이행을 담보하기 위해 계약자가 회사에 납부하는 금원을 말하며, 계약기간 만료 시 계약자가 모든 채무를 이행 완료한 경우 반환한다. | D10: ① 계약자는 관련 법령(이륜차 검사 포함), 관할관청의 지침 및 회사·매도인의 지시를 준수하여야 한다.
B11: ⑤ "계약자(라이더)"는 본 계약 제1면에 "계약자(라이더)"로 기재된 라이더 본인을 말하며, 본 계약상 주채무자이다. | D11: ② 회사는 계약기간 중 언제든 계약자의 본 계약 준수 여부를 점검할 수 있으며, 계약자는 성실히 협조하여야 한다.
B12: ⑥ "연대보증인(사업장)"은 본 계약 제1면에 기재된 사업장 및 그 대표자를 말하며, 계약자와 연대하여 본 계약상 채무를 부담함과 동시에 세금계산서 수취 대상을 겸한다. | D12: ③ 이륜차 보관·사용 등으로 제3자에게 손해가 발생한 경우 회사의 고의·과실이 없는 한 그 책임은 계약자가 부담한다. 보험 가입·처리 책임은 전적으로 계약자에게 있으며, 계약자의 귀책사유로 보험처리가 불가하거나 보험금으로 충당되지 않는 손해는 계약자가 부담한다.
B13: ⑦ "위약금"이란, 계약자의 귀책사유로 주문 취소 또는 중도 해지 시 회사에 지급하여야 하는 금액을 말한다. | D13: ④ 이륜차의 등록·유지·사용·등록말소·폐차 등과 관련하여 할부금에 포함되지 않은 비용 및 제세공과금(과태료·범칙금·벌과금 등)은 전적으로 계약자가 부담한다.
B14: ⑧ "지연손해금"이란, 계약자가 할부금·위약금·과태료 등의 납부를 지체한 경우 발생하는 추가 비용을 말한다.
B15: ⑨ "계약이관"이란, 계약자가 본 계약상의 권리와 의무를 제3자에게 승계하는 것을 말한다. | D15: 제14조 (금지행위)
D16: 계약자는 다음 행위를 하여서는 아니된다: (1) 이륜차를 양도·전대 또는 본 계약상 권리를 제3자에게 양도하는 행위, (2) 보험 인정 사용자 이외의 자에게 이륜차를 사용하게 하는 행위, (3) 이륜차 규격·성능·기능을 임의로 변경하거나 번호판을 훼손하는 행위, (4) 이륜차를 제3자에게 담보 목적으로 제공하는 등 회사의 소유권 침해 행위, (5) 이륜차 부착 표지를 제거·훼손하거나 내용·위치를 변경하는 행위.
B17: 제3조 (서류 제출 및 보완)
B18: ① 계약자는 본 계약 체결에 필요한 서류를 회사에 제출하여야 하며, 추후 보완 요구에도 성실히 응하여야 한다. | D18: 제15조 (제3자에 대한 면책)
B19: ② 제출된 서류는 어떠한 경우에도 반환하지 아니한다. | D19: ① 계약 기간 종료·해지 여부와 무관하게, 이륜차 인수일부터 반환일까지의 기간 동안 제3자가 회사(소유자)를 상대로 인적·물적 손해배상을 청구하는 경우 계약자는 자신의 비용·책임으로 회사를 면책시켜야 한다.
D20: ② 회사가 소유자라는 이유로 직접 손해배상을 한 경우 계약자는 회사가 제3자에게 지급한 금액과 관련 제비용을 즉시 상환하여야 한다.
B21: 제4조 (소유권 유보) | D21: ③ 회사가 제3자 청구에 방어를 한 경우 계약자는 방어 관련 지출된 소송비용 등 일체를 부담하여야 한다.
B22: ① 본 계약에 따른 이륜차의 소유권은 계약자가 모든 채무를 전액 이행할 때까지 회사에 유보된다.
B23: ② 계약자가 계약기간 동안 할부금을 성실히 납부하고 본 계약상 모든 채무를 완전히 이행한 경우, 회사는 지체 없이 이륜차의 소유권을 계약자에게 이전한다. | D23: 제16조 (계약자에 의한 중도 해지)
D24: ① 계약자가 본 계약을 중도 해지하고자 하는 경우 해지 예정일로부터 최소 10일 전에 회사에 사전 통보하여야 한다.
B25: 제5조 (계약자의 책임) | D25: ② 회사의 중대한 귀책사유가 아닌 경우 계약자는 제9조 및 계약에서 정한 위약금을 회사에 지급하여야 한다.
B26: ① 계약자는 선량한 관리자의 주의로 이륜차를 유지·관리하여야 하며, 운행 중 발생하는 모든 사고에 대해 책임을 부담한다. 회사가 소유권을 보유하더라도 운행자성이 없으므로 인적·물적 관리책임은 전적으로 계약자에게 있다. | D26: ③ 계약자는 해지 예정일까지 회사가 지정하는 장소에 이륜차를 반환하여야 하며, 관련 비용은 계약자가 부담한다.
B27: ② 계약자는 계약 기간 중 임의로 다른 부착물을 장착하거나 이륜차의 구조를 변경할 수 없다. | D27: ④ 최종 해지일은 이륜차가 회사에 반환된 날을 기준으로 하며, 계약자는 회사의 평가·정산 절차에 성실히 협조하여야 한다.
B28: ③ 이륜차의 소유권은 회사에 있으며, 계약자는 사용수익권과 운행이익권을 가진다. 제16조·제17조에 따라 계약이 해지된 경우 계약자는 즉시 운행을 중단하고 이륜차를 반환하여야 한다.
B29: ④ 계약자는 인수형 할부판매라 하더라도 계약기간 만료 및 약정 금액 완납 전에는 이륜차의 소유권을 주장할 수 없다. | D29: 제17조 (계약의 해지 사유)
B30: ⑤ 제3자가 이륜차에 대하여 권리를 주장하거나 보전처분·강제집행 등으로 회사의 소유권을 침해할 위험이 있는 경우, 계약자는 이륜차가 회사의 소유임을 주장·입증하여 침해를 방지하고 즉시 그 사실을 회사에 통지하여야 한다. | D30: 다음 각 호에 해당하는 경우 계약자는 사전 통지나 최고 없이 기한이익을 상실하며, 회사는 유보된 소유권에 근거하여 차량 인도를 청구한다: (1) 이륜차 무단 양도·전대, (2) 법령 위반 사용 또는 보험 인정 사용자 이외의 자에게 사용하게 하는 행위, (3) 정해진 입금일에 할부금 미납 및 보증금 이상 연체, (4) 통지받은 수리비·과태료 등을 정당한 사유 없이 5일 이내 미납, (5) 무면허·음주운전 등 사용자 귀책사유로 배상금이 청구된 후 3일 이내 미납, (6) 제3자 담보 제공 등 회사 소유권 침해행위, (7) 규격·성능 무단 변경, 부착 표지 임의 제거·훼손, (8) 위치정보 수집 장치 훼손·은닉.
B31: ⑥ 계약자는 이륜차를 인도받은 시점부터 반환 시까지 도난·멸실·훼손 등 일체의 사고에 대한 책임을 부담한다.
B32: ⑦ 이륜차 도난·멸실·훼손 시 계약자는 지체 없이 회사에 통보하고, 자신의 비용으로 (1) 이륜차를 원상태로 완전 복구 또는 (2) 동일 모델·사양으로 교체 중 하나를 이행하여야 한다. | D32: 제18조 (해지위약금 등의 부과방법)
B33: ⑧ 계약자는 계약 개시 시점에 차량·키·일체의 부속품을 인수하므로, 계약 종료 시까지 관련 도난·멸실·훼손에 대한 모든 책임을 부담한다. | D33: ① 위약금 산식: 위약금 = 보증금 + (잔여기간에 대한 총 할부금 × 20%). 계약자는 위약금을 계약 해지일까지 회사에 지급하여야 한다.
D34: ② 선납한 보증금은 어떠한 경우에도 반환되지 않는다.
B35: 제6조 (이륜차의 인도 및 계약자 확인) | D35: ③ 반환된 이륜차·부착물·키 부속품 일체에 파손이 있는 경우 계약자는 원상복구 수리비를 회사 청구일로부터 5일 이내에 지급하여야 한다.
B36: ① 계약 개시일은 계약자가 이륜차를 인도받은 날로 한다.
B37: ② 회사는 계약자가 인수증을 발급하거나 협력업체를 통해 직접 수령한 경우 해당 이륜차의 인도가 완료된 것으로 본다. | D37: 제19조 (이륜차 반환 및 회수)
B38: ③ 이륜차 인도 이후에는 계약자는 이륜차의 하자·결함을 이유로 할부금 지급의무를 거부할 수 없다. | D38: ① 제16조·제17조에 따라 계약이 해지되는 경우 계약자는 즉시 회사가 지정하는 장소로 이륜차를 반환하여야 한다.
D39: ② 계약자가 반환을 지연·거부하는 경우 회사는 이륜차를 임의로 회수할 수 있으며, 계약자는 민·형사상 어떠한 이의도 제기할 수 없다.
B40: 제7조 (보증금 및 계약금) | D40: ③ 회수에 소요된 일체의 비용은 계약자가 부담한다.
B41: ① 계약자는 계약 체결 시 회사가 지정하는 수납 대행사(포어스바이크 유한회사)의 계좌로 보증금을 지급하여야 한다. 사전 동의를 받아 보증금 지급이 지연된 경우 회사는 최대 7일의 유예기간을 둘 수 있다. | D41: ④ 계약자는 계약 해지일부터 이륜차 최종 반환일까지의 손해배상금을 회사에 지급하여야 한다.
...
